Workbook

Sheet MONSTER (MNST)
B1: MONSTER
B2: COMMON SIZING AND TREND ANALYSIS (in 000's Except Per Share Data)
B3: INCOME STATEMENT DATA
B4: NAME | U4: Page 1 of 3
B5: FIN320 Section B
J6: Common-Size Analysis | Q6: Trend Analysis
J7: (as a percentage of sales) | Q7: (using 2020 as the base year)
B8: Income Statement | C8: 2021 | D8: 2022 | E8: 2023 | F8: 2024 | G8: 2025 | J8: 2021 | K8: 2022 | L8: 2023 | M8: 2024 | N8: 2025 | Q8: 2021 | R8: 2022 | S8: 2023 | T8: 2024 | U8: 2025
B9: Net Operating Revenues | C9: 5541.352 | D9: 6311.05 | E9: 7140.027 | F9: 7492.709 | G9: 8294.343 | J9: =C9/C$9 -> 1 | K9: =D9/D$9 -> 1 | L9: =E9/E$9 -> 1 | M9: =F9/F$9 -> 1 | N9: =G9/G$9 -> 1 | Q9: =C9/$C9 -> 1 | R9: =D9/$C9 -> 1.1389008 | S9: =E9/$C9 -> 1.2884991 | T9: =F9/$C9 -> 1.3521446 | U9: =G9/$C9 -> 1.4968085
B10: Cost of sales | C10: 2432.839 | D10: 3136.483 | E10: 3345.821 | F10: 3443.831 | G10: 3662.148 | J10: =C10/C$9 -> 0.43903347 | K10: =D10/D$9 -> 0.49698275 | L10: =E10/E$9 -> 0.46860061 | M10: =F10/F$9 -> 0.45962428 | N10: =G10/G$9 -> 0.44152358 | Q10: =C10/$C10 -> 1 | R10: =D10/$C10 -> 1.2892275 | S10: =E10/$C10 -> 1.3752743 | T10: =F10/$C10 -> 1.4155606 | U10: =G10/$C10 -> 1.5052981
B11: Gross Profit | C11: =C9-C10 -> 3108.513 | D11: =D9-D10 -> 3174.567 | E11: =E9-E10 -> 3794.206 | F11: =F9-F10 -> 4048.878 | G11: =G9-G10 -> 4632.195 | J11: =C11/C$9 -> 0.56096653 | K11: =D11/D$9 -> 0.50301725 | L11: =E11/E$9 -> 0.53139939 | M11: =F11/F$9 -> 0.54037572 | N11: =G11/G$9 -> 0.55847642 | Q11: =C11/$C11 -> 1 | R11: =D11/$C11 -> 1.0212494 | S11: =E11/$C11 -> 1.2205855 | T11: =F11/$C11 -> 1.3025128 | U11: =G11/$C11 -> 1.4901643
B13: Operating expenses
B14: Selling, general and administrative expenses
B15: Other operating charges | C15: 1311.046 | D15: 1589.846 | E15: 1840.851 | F15: 2118.584 | G15: 2212.841 | J15: =C15/C$9 -> 0.23659316 | K15: =D15/D$9 -> 0.25191466 | L15: =E15/E$9 -> 0.25782129 | M15: =F15/F$9 -> 0.28275274 | N15: =G15/G$9 -> 0.26678918 | Q15: =C15/$C15 -> 1 | R15: =D15/$C15 -> 1.2126546 | S15: =E15/$C15 -> 1.4041086 | T15: =F15/$C15 -> 1.6159494 | U15: =G15/$C15 -> 1.6878439
B16: Total Oper. Exp | C16: =+C14+C15 -> 1311.046 | D16: =+D14+D15 -> 1589.846 | E16: =+E14+E15 -> 1840.851 | F16: =+F14+F15 -> 2118.584 | G16: =+G14+G15 -> 2212.841 | J16: =C16/C$9 -> 0.23659316 | K16: =D16/D$9 -> 0.25191466 | L16: =E16/E$9 -> 0.25782129 | M16: =F16/F$9 -> 0.28275274 | N16: =G16/G$9 -> 0.26678918 | Q16: =C16/$C16 -> 1 | R16: =D16/$C16 -> 1.2126546 | S16: =E16/$C16 -> 1.4041086 | T16: =F16/$C16 -> 1.6159494 | U16: =G16/$C16 -> 1.6878439
B18: Operating Income (EBIT) | C18: =C11-C16 -> 1797.467 | D18: =D11-D16 -> 1584.721 | E18: =E11-E16 -> 1953.355 | F18: =F11-F16 -> 1930.294 | G18: =G11-G16 -> 2419.354 | J18: =C18/C$9 -> 0.32437337 | K18: =D18/D$9 -> 0.25110259 | L18: =E18/E$9 -> 0.2735781 | M18: =F18/F$9 -> 0.25762298 | N18: =G18/G$9 -> 0.29168724 | Q18: =C18/$C18 -> 1 | R18: =D18/$C18 -> 0.88164122 | S18: =E18/$C18 -> 1.0867265 | T18: =F18/$C18 -> 1.0738968 | U18: =G18/$C18 -> 1.3459796
B19: Interest income
B20: Interest income / (expense) | C20: -3.952 | D20: 12.757 | E20: -115.127 | F20: -59.165 | G20: -63.175 | J20: =C20/C$9 -> -0.00071318335 | K20: =D20/D$9 -> 0.0020213752 | L20: =E20/E$9 -> -0.016124169 | M20: =F20/F$9 -> -0.007896343 | N20: =G20/G$9 -> -0.007616637 | Q20: =C20/$C20 -> 1 | R20: =D20/$C20 -> -3.2279858 | S20: =E20/$C20 -> 29.131326 | T20: =F20/$C20 -> 14.970901 | U20: =G20/$C20 -> 15.985577
B21: Equity income (loss) - net
B22: Other income (loss) - net
B24: Pretax Income | C24: =C18+C19-C20+C21+C22 -> 1801.419 | D24: =D18+D19-D20+D21+D22 -> 1571.964 | E24: =E18+E19-E20+E21+E22 -> 2068.482 | F24: =F18+F19-F20+F21+F22 -> 1989.459 | G24: =G18+G19-G20+G21+G22 -> 2482.529 | J24: =C24/C$9 -> 0.32508655 | K24: =D24/D$9 -> 0.24908121 | L24: =E24/E$9 -> 0.28970227 | M24: =F24/F$9 -> 0.26551932 | N24: =G24/G$9 -> 0.29930387 | Q24: =C24/$C24 -> 1 | R24: =D24/$C24 -> 0.87262541 | S24: =E24/$C24 -> 1.1482515 | T24: =F24/$C24 -> 1.1043844 | U24: =G24/$C24 -> 1.3780964
B25: Provision for income taxes | C25: 423.944 | D25: 380.34 | E25: 437.494 | F25: 480.411 | G25: 577.097 | J25: =C25/C$9 -> 0.076505517 | K25: =D25/D$9 -> 0.060265724 | L25: =E25/E$9 -> 0.061273438 | M25: =F25/F$9 -> 0.06411713 | N25: =G25/G$9 -> 0.06957718 | Q25: =C25/$C25 -> 1 | R25: =D25/$C25 -> 0.89714679 | S25: =E25/$C25 -> 1.0319618 | T25: =F25/$C25 -> 1.1331945 | U25: =G25/$C25 -> 1.3612576
B26: Effective Tax rate | C26: =C25/C24 -> 0.23533892 | D26: =D25/D24 -> 0.24195211 | E26: =E25/E24 -> 0.21150486 | F26: =F25/F24 -> 0.24147821 | G26: =G25/G24 -> 0.23246335 | J26: =C26/C$9 -> 4.2469585e-05 | K26: =D26/D$9 -> 3.8337853e-05 | L26: =E26/E$9 -> 2.9622418e-05 | M26: =F26/F$9 -> 3.2228425e-05 | N26: =G26/G$9 -> 2.8026734e-05 | Q26: =C26/$C26 -> 1 | R26: =D26/$C26 -> 1.0281007 | S26: =E26/$C26 -> 0.89872454 | T26: =F26/$C26 -> 1.026087 | U26: =G26/$C26 -> 0.98778115
B28: Net income | C28: =C24-C25 -> 1377.475 | D28: =D24-D25 -> 1191.624 | E28: =E24-E25 -> 1630.988 | F28: =F24-F25 -> 1509.048 | G28: =G24-G25 -> 1905.432 | J28: =C28/C$9 -> 0.24858103 | K28: =D28/D$9 -> 0.18881549 | L28: =E28/E$9 -> 0.22842883 | M28: =F28/F$9 -> 0.20140219 | N28: =G28/G$9 -> 0.22972669 | Q28: =C28/$C28 -> 1 | R28: =D28/$C28 -> 0.8650785 | S28: =E28/$C28 -> 1.1840418 | T28: =F28/$C28 -> 1.0955175 | U28: =G28/$C28 -> 1.3832788
B30: Number of Shares Outstanding | C30: 528.763 | D30: 526.779 | E30: 1044.887 | F30: 1004.566 | G30: 975.887
B31: Stock Price | C31: 42 | D31: 44 | E31: 44 | F31: 55 | G31: 79
B35: Depreciation and amortization | C35: 5.155 | D35: 61.241 | E35: 68.898 | F35: 80.434 | G35: 114.441
B36: Dividends Paid
B37: Net Cash Provided by Operating Activities
B38: Purchases of property, plant and equipment
B41: MONSTER
B42: COMMON SIZING AND TREND ANALYSIS (in 000's Except Per Share Data)
B43: BALANCE SHEET DATA
B44: YOUR NAME | U44: Page 2 of 3
B45: =B5 -> FIN320 Section B
J47: Common-Size Analysis | Q47: Trend Analysis
J48: (as a percentage of total assets) | Q48: (using 2021 as a base year)
B49: Balance Sheet | C49: 2021 | D49: 2022 | E49: 2023 | F49: 2024 | G49: 2025 | J49: 2021 | K49: 2022 | L49: 2023 | M49: 2024 | N49: 2025 | Q49: 2021 | R49: 2022 | S49: 2023 | T49: 2024 | U49: 2025
B50: ASSETS:
B51: Current assets:
...

Sheet Monster data sheet
I2: CONSOLIDATED BALANCE SHEETS - USD ($) | J2: Dec. 31, 2025 | K2: Dec. 31, 2024 | L2: Dec. 31, 2023 | M2: Dec. 31, 2022 | N2: Dec. 31, 2021 | O2: Dec. 31, 2020
I3: $ in Thousands
I4: CURRENT ASSETS:
I5: Cash and cash equivalents | J5: 2088117 | K5: 1533287 | L5: 2297675 | M5: 1307141 | N5: 1326462 | O5: 1180413
B6: CONSOLIDATED STATEMENTS OF INCOME - USD ($) | C6: 12 Months Ended | I6: Short-term investments | J6: 677084 | K6: 0 | L6: 955605 | M6: 1362314 | N6: 1749727 | O6: 881354
B7: shares in Thousands, $ in Thousands | I7: Accounts receivable, net | J7: 1618072 | K7: 1221646 | L7: 1193964 | M7: 1016203 | N7: 896658 | O7: 666012
B8: Dec. 31, 2025 | C8: Dec. 31, 2025 | D8: Dec. 31, 2024 | E8: Dec. 31, 2023 | F8: Dec. 31, 2022 | G8: Dec. 31, 2021 | I8: Inventories | J8: 799623 | K8: 737107 | L8: 971406 | M8: 935631 | N8: 593357 | O8: 333085
B9: CONSOLIDATED STATEMENTS OF INCOME | I9: Prepaid expenses and other current assets | J9: 103551 | K9: 107262 | L9: 116195 | M9: 109823 | N9: 82668 | O9: 55358
B10: NET SALES | C10: 8294343 | D10: 7492709 | E10: 7140027 | F10: 6311050 | G10: 5541352 | I10: Prepaid income taxes | J10: 74637 | K10: 42202 | L10: 54151 | M10: 33785 | N10: 33238 | O10: 24733
B11: COST OF SALES | C11: 3662148 | D11: 3443831 | E11: 3345821 | F11: 3136483 | G11: 2432839 | I11: Total current assets | J11: 5361084 | K11: 3641504 | L11: 5588996 | M11: 4764897 | N11: 4682110 | O11: 3140955
B12: GROSS PROFIT | C12: 4632195 | D12: 4048878 | E12: 3794206 | F12: 3174567 | G12: 3108513 | I12: INVESTMENTS | J12: 487329 | K12: 0 | L12: 76431 | M12: 61443 | N12: 99419 | O12: 44291
B13: OPERATING EXPENSES | C13: 2212841 | D13: 2118584 | E13: 1840851 | F13: 1589846 | G13: 1311046 | I13: PROPERTY AND EQUIPMENT, net | J13: 1081544 | K13: 1047024 | L13: 890796 | M13: 516897 | N13: 313753 | O13: 314656
B14: OPERATING INCOME | C14: 2419354 | D14: 1930294 | E14: 1953355 | F14: 1584721 | G14: 1797467 | I14: DEFERRED INCOME TAXES, net | J14: 188646 | K14: 184260 | L14: 175003 | M14: 177039 | N14: 225221 | O14: 241650
B15: INTEREST AND OTHER INCOME, NET | C15: 63175 | D15: 59165 | E15: 115127 | F15: -12757 | G15: 3952 | I15: GOODWILL | J15: 1331643 | K15: 1331643 | L15: 1417941 | M15: 1417941 | N15: 1331643 | O15: 1331643
B16: INCOME BEFORE PROVISION FOR INCOME TAXES | C16: 2482529 | D16: 1989459 | E16: 2068482 | F16: 1571964 | G16: 1801419 | I16: OTHER INTANGIBLE ASSETS, net | J16: 1379268 | K16: 1414252 | L16: 1427139 | M16: 1220410 | N16: 1072386 | O16: 1059046
B17: PROVISION FOR INCOME TAXES | C17: 577097 | D17: 480411 | E17: 437494 | F17: 380340 | G17: 423944 | I17: OTHER ASSETS | J17: 159431 | K17: 100406 | L17: 110216 | M17: 134478 | N17: 80252 | O17: 70475
B18: NET INCOME | C18: 1905432 | D18: 1509048 | E18: 1630988 | F18: 1191624 | G18: 1377475 | I18: Total Assets | J18: 9988945 | K18: 7719089 | L18: 9686522 | M18: 8293105 | N18: 7804784 | O18: 6202716
B19: NET INCOME PER COMMON SHARE: | I19: CURRENT LIABILITIES:
B20: Basic (in dollar per share) | C20: 1.95 | D20: 1.5 | E20: 1.56 | F20: 2.26 | G20: 2.61 | I20: Accounts payable | J20: 565974 | K20: 466775 | L20: 564379 | M20: 444265 | N20: 404263 | O20: 296800
B21: Diluted (in dollar per share) | C21: 1.94 | D21: 1.49 | E21: 1.54 | F21: 2.23 | G21: 2.57 | I21: Accrued liabilities | J21: 306085 | K21: 220764 | L21: 183988 | M21: 172991 | N21: 210964 | O21: 142653
B22: Basic (in shares) | C22: 975887 | D22: 1004566 | E22: 1044887 | F22: 526779 | G22: 528763 | I22: Accrued promotional allowances | J22: 384070 | K22: 267711 | L22: 269061 | M22: 255631 | N22: 211461 | O22: 186658
B23: Diluted (in shares) | C23: 984451 | D23: 1013107 | E23: 1057981 | F23: 533221 | G23: 535639 | I23: Deferred revenue | J23: 45323 | K23: 45809 | L23: 41914 | M23: 43311 | N23: 42530 | O23: 45429
I24: Accrued compensation | J24: 114023 | K24: 92454 | L24: 87392 | M24: 72463 | N24: 65459 | O24: 55015
I25: Income taxes payable | J25: 32305 | K25: 4006 | L25: 14955 | M25: 13317 | N25: 30399 | O25: 23433
I26: Total current liabilities | J26: 1447780 | K26: 1097519 | L26: 1161689 | M26: 1001978 | N26: 965076 | O26: 749988
I27: DEFERRED REVENUE | J27: 159991 | K27: 179008 | L27: 204251 | M27: 223800 | N27: 243249 | O27: 264436
I28: OTHER LIABILITIES | J28: 127066 | K28: 110893 | L28: 91838 | M28: 42286 | N28: 29508 | O28: 27432
I29: LONG-TERM DEBT | K29: 373951
I30: COMMITMENTS AND CONTINGENCIES (Note 10)
I31: STOCKHOLDERS' EQUITY:
I32: Common stock - $0.005 par value; 5,000,000 shares authorized; 1,132,906 shares issued and 978,113 shares outstanding as of December 31, 2025; 1,126,329 shares issued and 973,079 shares outstanding as of December 31, 2024 | J32: 5665 | K32: 5632 | L32: 5613 | M32: 3209 | N32: 3200 | O32: 3193
I33: Additional paid-in capital | J33: 5430847 | K33: 5144922 | L33: 4975115 | M33: 4780013 | N33: 4652620 | O33: 4537982
I34: Retained earnings | J34: 9354216 | K34: 7448784 | L34: 5939736 | M34: 9001173 | N34: 7809549 | O34: 6432074
I35: Accumulated other comprehensive loss | J35: -60841 | K35: -269487 | L35: -125337 | M35: -159073 | N35: -69165 | O35: 3034
I36: Common stock in treasury, at cost; 154,793 shares and 153,250 shares as of December 31, 2025 and December 31, 2024, respectively | J36: -6475779 | K36: -6372133 | L36: -2566383 | M36: -6600281 | N36: -5829253 | O36: -5815423
I37: Total stockholders' equity | J37: 8254108 | K37: 5957718 | L37: 8228744 | M37: 7025041 | N37: 6566951 | O37: 5160860
I38: Total Liabilities and Stockholders' Equity | J38: 9988945 | K38: 7719089 | L38: 9686522 | M38: 8293105 | N38: 7804784 | O38: 6202716

Sheet PepsiCo (PEP)
A1: PEPSI CO
A2: COMMON SIZING AND TREND ANALYSIS (in 000's Except Per Share Data)
A3: INCOME STATEMENT DATA
I4: Common-Size Analysis | P4: Trend Analysis
I5: (as a percentage of sales) | P5: (using 2020 as the base year)
A6: Income Statement | B6: 2021 | C6: 2022 | D6: 2023 | E6: 2024 | F6: 2025 | I6: 2021 | J6: 2022 | K6: 2023 | L6: 2024 | M6: 2025 | P6: 2021 | Q6: 2022 | R6: 2023 | S6: 2024 | T6: 2025
A7: Revenue | B7: 79474 | C7: 86392 | D7: 91471 | E7: 91854 | F7: 93925 | I7: =B7/$B$7 -> 1 | J7: =C7/$C$7 -> 1 | K7: =D7/$D$7 -> 1 | L7: =E7/$E$7 -> 1 | M7: =F7/$F$7 -> 1 | P7: =B7/$B$7 -> 1 | Q7: =C7/$B$7 -> 1.0870473 | R7: =D7/$B$7 -> 1.150955 | S7: =E7/$B$7 -> 1.1557742 | T7: =F7/$B$7 -> 1.1818331
A8: Cost of sales | B8: 37075 | C8: 40576 | D8: 41881 | E8: 41744 | F8: 43066 | I8: =B8/$B$7 -> 0.46650477 | J8: =C8/$C$7 -> 0.46967312 | K8: =D8/$D$7 -> 0.45786096 | L8: =E8/$E$7 -> 0.45446034 | M8: =F8/$F$7 -> 0.45851477 | P8: =B8/$B$8 -> 1 | Q8: =C8/$B$8 -> 1.0944302 | R8: =D8/$B$8 -> 1.1296291 | S8: =E8/$B$8 -> 1.1259339 | T8: =F8/$B$8 -> 1.1615914
A9: Gross Profit | B9: 42399 | C9: 45816 | D9: 49590 | E9: 50110 | F9: 50859 | I9: =B9/$B$7 -> 0.53349523 | J9: =C9/$C$7 -> 0.53032688 | K9: =D9/$D$7 -> 0.54213904 | L9: =E9/$E$7 -> 0.54553966 | M9: =F9/$F$7 -> 0.54148523 | P9: =B9/$B$9 -> 1 | Q9: =C9/$B$9 -> 1.0805915 | R9: =D9/$B$9 -> 1.1696031 | S9: =E9/$B$9 -> 1.1818675 | T9: =F9/$B$9 -> 1.199533
A11: Operating expenses
A12: SGA | B12: 31237 | C12: 34459 | D12: 36677 | E12: 37190 | F12: 37368 | I12: =B12/$B$7 -> 0.39304678 | J12: =C12/$C$7 -> 0.39886795 | K12: =D12/$D$7 -> 0.40096861 | L12: =E12/$E$7 -> 0.40488166 | M12: =F12/$F$7 -> 0.39784935 | P12: =B12/$B$12 -> 1 | Q12: =C12/$B$12 -> 1.1031469 | R12: =D12/$B$12 -> 1.1741524 | S12: =E12/$B$12 -> 1.1905753 | T12: =F12/$B$12 -> 1.1962736
A13: Impairment of Intangible Assets (Excluding Goodwill) | B13: 0 | C13: 3166 | D13: 927 | E13: 33 | F13: 1993 | I13: =B13/$B$7 -> 0 | J13: =C13/$C$7 -> 0.036646912 | K13: =D13/$D$7 -> 0.01013436 | L13: =E13/$E$7 -> 0.00035926579 | M13: =F13/$F$7 -> 0.021219058 | P13: =B13/$B$12 -> 0 | Q13: =C13/$B$12 -> 0.10135416 | R13: =D13/$B$12 -> 0.029676345 | S13: =E13/$B$12 -> 0.0010564395 | T13: =F13/$B$12 -> 0.063802542
A14: Gain associated with the Juice Transaction | B14: 0 | C14: -3321 | D14: 0 | E14: 0 | F14: 0 | I14: =B14/$B$7 -> 0 | J14: =C14/$C$7 -> -0.038441059 | K14: =D14/$D$7 -> 0 | L14: =E14/$E$7 -> 0 | M14: =F14/$F$7 -> 0 | P14: =B14/$B$12 -> 0 | Q14: =C14/$B$12 -> -0.10631623 | R14: =D14/$B$12 -> 0 | S14: =E14/$B$12 -> 0 | T14: =F14/$B$12 -> 0
A15: Total Oper. Exp | B15: =SUM(B12:B14) -> 31237 | C15: =SUM(C12:C14) -> 34304 | D15: =SUM(D12:D14) -> 37604 | E15: =SUM(E12:E14) -> 37223 | F15: =SUM(F12:F14) -> 39361
P16: =B16/$B$12 -> 0 | Q16: =C16/$B$12 -> 0 | R16: =D16/$B$12 -> 0 | S16: =E16/$B$12 -> 0 | T16: =F16/$B$12 -> 0
A17: Operating Income (EBIT) | B17: 11162 | C17: 11512 | D17: 11986 | E17: 12887 | F17: 11498 | I17: =B17/$B$7 -> 0.14044845 | J17: =C17/$C$7 -> 0.13325308 | K17: =D17/$D$7 -> 0.13103607 | L17: =E17/$E$7 -> 0.14029873 | M17: =F17/$F$7 -> 0.12241682 | P17: =B17/$B$17 -> 1 | Q17: =C17/$B$17 -> 1.0313564 | R17: =D17/$B$17 -> 1.0738219 | S17: =E17/$B$17 -> 1.1545422 | T17: =F17/$B$17 -> 1.0301021
A18: Interest Expense | B18: 1863 | C18: 939 | D18: 819 | E18: 919 | F18: 1121 | I18: =B18/$B$7 -> 0.023441629 | J18: =C18/$C$7 -> 0.010869062 | K18: =D18/$D$7 -> 0.0089536574 | L18: =E18/$E$7 -> 0.010005008 | M18: =F18/$F$7 -> 0.011935055 | P18: =B18/$B$18 -> 1 | Q18: =C18/$B$18 -> 0.50402576 | R18: =D18/$B$18 -> 0.43961353 | S18: =E18/$B$18 -> 0.49329039 | T18: =F18/$B$18 -> 0.60171766
A19: Other expenses (net) | B19: 522 | C19: 132 | D19: 250 | E19: -22 | F19: -133 | I19: =B19/$B$7 -> 0.0065681858 | J19: =C19/$C$7 -> 0.0015279193 | K19: =D19/$D$7 -> 0.0027331067 | L19: =E19/$E$7 -> -0.00023951053 | M19: =F19/$F$7 -> -0.0014160234 | P19: =B19/$B$19 -> 1 | Q19: =C19/$B$19 -> 0.25287356 | R19: =D19/$B$19 -> 0.4789272 | S19: =E19/$B$19 -> -0.042145594 | T19: =F19/$B$19 -> -0.25478927
A21: Pretax Income | B21: 9821 | C21: 10705 | D21: 11417 | E21: 11946 | F21: 10244 | I21: =B21/$B$7 -> 0.12357501 | J21: =C21/$C$7 -> 0.12391194 | K21: =D21/$D$7 -> 0.12481552 | L21: =E21/$E$7 -> 0.13005422 | M21: =F21/$F$7 -> 0.10906574 | P21: =B21/$B$21 -> 1 | Q21: =C21/$B$21 -> 1.0900112 | R21: =D21/$B$21 -> 1.1625089 | S21: =E21/$B$21 -> 1.2163731 | T21: =F21/$B$21 -> 1.043071
A22: Provision for income taxes | B22: 2142 | C22: 1727 | D22: 2262 | E22: 2320 | F22: 1949 | I22: =B22/$B$7 -> 0.026952211 | J22: =C22/$C$7 -> 0.019990277 | K22: =D22/$D$7 -> 0.024729149 | L22: =E22/$E$7 -> 0.025257474 | M22: =F22/$F$7 -> 0.020750599 | P22: =B22/$B$22 -> 1 | Q22: =C22/$B$22 -> 0.80625584 | R22: =D22/$B$22 -> 1.0560224 | S22: =E22/$B$22 -> 1.0830999 | T22: =F22/$B$22 -> 0.90989729
A23: Effective Tax rate | B23: =B22/B21 -> 0.21810406 | C23: =C22/C21 -> 0.16132648 | D23: =D22/D21 -> 0.1981256 | E23: =E22/E21 -> 0.19420727 | F23: =F22/F21 -> 0.19025771
A25: Net income | B25: 7679 | C25: 8978 | D25: 9155 | E25: 9626 | F25: 8295 | I25: =B25/$B$7 -> 0.096622795 | J25: =C25/$C$7 -> 0.10392166 | K25: =D25/$D$7 -> 0.10008637 | L25: =E25/$E$7 -> 0.10479674 | M25: =F25/$F$7 -> 0.088315145 | P25: =B25/$B$25 -> 1 | Q25: =C25/$B$25 -> 1.1691627 | R25: =D25/$B$25 -> 1.1922125 | S25: =E25/$B$25 -> 1.2535486 | T25: =F25/$B$25 -> 1.0802188
A27: Number of Shares Outstanding | B27: 1382 | C27: 1380 | D27: 1376 | E27: 1373 | F27: 1369
A28: Stock Price | B28: 151.88 | C28: 162.18 | D28: 156.85 | E28: 144.92 | F28: 142.25
A30: Depreciation and amortization | B30: 2710 | C30: 2763 | D30: 2948 | E30: 3160 | F30: 3451
A31: Dividends Paid | B31: 5815 | C31: 6172 | D31: 6682 | E31: 7229 | F31: 7638
A32: Net Cash Provided by Operating Activities | B32: 11616 | C32: 10811 | D32: 13442 | E32: 12507 | F32: 12087
A33: Purchases of property, plant and equipment | B33: 4459 | C33: 4956 | D33: 5320 | E33: 4976 | F33: 3887
A34: Free cash flow | B34: =B32-B33 -> 7157 | C34: =C32-C33 -> 5855 | D34: =D32-D33 -> 8122 | E34: =E32-E33 -> 7531 | F34: =F32-F33 -> 8200
A45: PEPSI CO
A46: COMMON SIZING AND TREND ANALYSIS (in 000's Except Per Share Data)
A47: BALANCE SHEET DATA
I49: Common-Size Analysis | P49: Trend Analysis
I50: (as a percentage of total assets) | P50: (using 2020 as a base year)
A51: Balance Sheet | B51: 2021 | C51: 2022 | D51: 2023 | E51: 2024 | F51: 2025 | I51: 2021 | J51: 2022 | K51: 2023 | L51: 2024 | M51: 2025 | P51: 2021 | Q51: 2022 | R51: 2023 | S51: 2024 | T51: 2025
A52: ASSETS:
A53: Current assets:
A54: Cash/Cash equivalents | B54: ='Pepsi data sheet'!B32 -> 5596 | C54: ='Pepsi data sheet'!C32 -> 4964 | D54: ='Pepsi data sheet'!D32 -> 9711 | E54: ='Pepsi data sheet'!E32 -> 8505 | F54: ='Pepsi data sheet'!F32 -> 9159 | I54: =B54/$B$68 -> 0.060577849 | J54: =C54/$C$68 -> 0.053841231 | K54: =D54/$D$68 -> 0.096631673 | L54: =E54/$E$68 -> 0.085505746 | M54: =F54/$F$68 -> 0.085280124 | P54: =B54/$B$54 -> 1 | Q54: =C54/$B$54 -> 0.88706219 | R54: =D54/$B$54 -> 1.7353467 | S54: =E54/$B$54 -> 1.5198356 | T54: =F54/$B$54 -> 1.6367048
A55: Short-term market sect | B55: ='Pepsi data sheet'!B33 -> 392 | C55: ='Pepsi data sheet'!C33 -> 394 | D55: ='Pepsi data sheet'!D33 -> 292 | E55: ='Pepsi data sheet'!E33 -> 761 | F55: ='Pepsi data sheet'!F33 -> 371 | I55: =B55/$B$68 -> 0.0042434805 | J55: =C55/$C$68 -> 0.0042734579 | K55: =D55/$D$68 -> 0.0029056172 | L55: =E55/$E$68 -> 0.0076507787 | M55: =F55/$F$68 -> 0.0034544083 | P55: =B55/$B$55 -> 1 | Q55: =C55/$B$55 -> 1.005102 | R55: =D55/$B$55 -> 0.74489796 | S55: =E55/$B$55 -> 1.9413265 | T55: =F55/$B$55 -> 0.94642857
A56: Accounts receivable | B56: ='Pepsi data sheet'!B34 -> 8680 | C56: ='Pepsi data sheet'!C34 -> 10163 | D56: ='Pepsi data sheet'!D34 -> 10815 | E56: ='Pepsi data sheet'!E34 -> 10333 | F56: ='Pepsi data sheet'!F34 -> 11506 | I56: =B56/$B$68 -> 0.093962783 | J56: =C56/$C$68 -> 0.11023135 | K56: =D56/$D$68 -> 0.10761729 | L56: =E56/$E$68 -> 0.1038837 | M56: =F56/$F$68 -> 0.10713321 | P56: =B56/$B$56 -> 1 | Q56: =C56/$B$56 -> 1.1708525 | R56: =D56/$B$56 -> 1.2459677 | S56: =E56/$B$56 -> 1.1904378 | T56: =F56/$B$56 -> 1.325576
...

Sheet Pepsi data sheet
A1: Consolidated Statement of Income - USD ($) | B1: 12 Months Ended
A2: shares in Millions, $ in Millions
B3: Dec. 25, 2021 | C3: Dec. 31, 2022 | D3: Dec. 30, 2023 | E3: Dec. 28, 2024 | F3: Dec. 27, 2025
A4: Income Statement [Abstract]
A5: Net Revenue | B5: 79474 | C5: 86392 | D5: 91471 | E5: 91854 | F5: 93925 | H5: =C5-C6 -> 45816
A6: Cost of sales | B6: 37075 | C6: 40576 | D6: 41881 | E6: 41744 | F6: 43066 | H6: =SUM(C8:C10) -> 34304
A7: Gross profit | B7: 42399 | C7: 45816 | D7: 49590 | E7: 50110 | F7: 50859 | H7: =H5-H6 -> 11512
A8: Selling, general and administrative expenses | B8: 31237 | C8: 34459 | D8: 36677 | E8: 37190 | F8: 37368
A9: Gain associated with the Juice Transaction | B9: 0 | C9: -3321 | D9: 0 | E9: 0 | F9: 0
A10: Impairment of Intangible Assets (Excluding Goodwill) | B10: 0 | C10: 3166 | D10: 927 | E10: 33 | F10: 1993
A11: Operating Profit | B11: 11162 | C11: 11512 | D11: 11986 | E11: 12887 | F11: 11498
A12: Other pension and retiree medical benefits (expense)/income | B12: 522 | C12: 132 | D12: 250 | E12: -22 | F12: -133
A13: Net interest expense and other | B13: -1863 | C13: -939 | D13: -819 | E13: -919 | F13: -1121
A14: Income before income taxes | B14: 9821 | C14: 10705 | D14: 11417 | E14: 11946 | F14: 10244
A15: Provision for income taxes | B15: 2142 | C15: 1727 | D15: 2262 | E15: 2320 | F15: 1949
A16: Net income | B16: 7679 | C16: 8978 | D16: 9155 | E16: 9626 | F16: 8295
A17: Less: Net income attributable to noncontrolling interests | B17: 61 | C17: 68 | D17: 81 | E17: 48 | F17: 55
A18: Net Income Attributable to PepsiCo | B18: $7,618 | C18: $8,910 | D18: $9,074 | E18: $9,578 | F18: $8,240
A20: Net Income Attributable to PepsiCo per Common Share
A21: Basic | B21: $5.51 | C21: $6.45 | D21: $6.59 | E21: $6.97 | F21: $6.02
A22: Diluted | B22: $5.49 | C22: $6.42 | D22: $6.56 | E22: $6.95 | F22: $6.00
A23: Weighted-average common shares outstanding
A24: Basic | B24: 1382 | C24: 1380 | D24: 1376 | E24: 1373 | F24: 1369
A25: Diluted | B25: 1389 | C25: 1387 | D25: 1383 | E25: 1378 | F25: 1373
A29: Consolidated Balance Sheet - USD ($) | B29: 12 Months Ended
A30: shares in Millions, $ in Millions | B30: Dec. 25, 2021 | C30: Dec. 31, 2022 | D30: Dec. 30, 2023 | E30: Dec. 28, 2024 | F30: Dec. 27, 2025
A31: ASSETS
A32: Cash and cash equivalents | B32: 5596 | C32: 4964 | D32: 9711 | E32: 8505 | F32: 9159
A33: Short-term Investments | B33: 392 | C33: 394 | D33: 292 | E33: 761 | F33: 371
A34: Accounts and notes receivable, net | B34: 8680 | C34: 10163 | D34: 10815 | E34: 10333 | F34: 11506
A35: Inventories | B35: 4347 | C35: 5222 | D35: 5334 | E35: 5306 | F35: 5845
A36: Prepaid expenses and other current assets | B36: 980 | C36: 806 | D36: 798 | E36: 921 | F36: 1068
A37: Disposal Group, Including Discontinued Operation, Assets | B37: 1788
A38: Assets, Current | B38: 21783 | C38: 21539 | D38: 26950 | E38: 25826 | F38: 27949
A39: Property, Plant and Equipment, net | B39: 22407 | C39: 24291 | D39: 27039 | E39: 28008 | F39: 29905
A40: Amortizable Intangible Assets, net | B40: 1538 | C40: 1277 | D40: 1199 | E40: 1102 | F40: 1219
A41: Goodwill | B41: 18381 | C41: 18202 | D41: 17728 | E41: 17534 | F41: 18916
A42: Indefinite-lived Intangible Assets (Excluding Goodwill) | B42: 17127 | C42: 14309 | D42: 13730 | E42: 13699 | F42: 13847
A43: Equity Method Investments | B43: 2350 | C43: 3073 | D43: 2714 | E43: 1985 | F43: 2038
A44: Deferred Income Tax Assets, Net | B44: 4310 | C44: 4204 | D44: 4474 | E44: 4362 | F44: 4541
...

Sheet Coca Cola (KO)
B1: COCA COLA
B2: COMMON SIZING AND TREND ANALYSIS (in 000's Except Per Share Data)
B3: INCOME STATEMENT DATA
B4: NAME | U4: Page 1 of 3
B5: FIN320 Section B
J6: Common-Size Analysis | Q6: Trend Analysis
J7: (as a percentage of sales) | Q7: (using 2020 as the base year)
B8: Income Statement | C8: 2021 | D8: 2022 | E8: 2023 | F8: 2024 | G8: 2025 | J8: 2021 | K8: 2022 | L8: 2023 | M8: 2024 | N8: 2025 | Q8: 2021 | R8: 2022 | S8: 2023 | T8: 2024 | U8: 2025
B9: Net Operating Revenues | C9: 38655 | D9: 43004 | E9: 45754 | F9: 47061 | G9: 47941 | J9: =C9/C$9 -> 1 | K9: =D9/D$9 -> 1 | L9: =E9/E$9 -> 1 | M9: =F9/F$9 -> 1 | N9: =G9/G$9 -> 1 | Q9: =C9/$C9 -> 1 | R9: =D9/$C9 -> 1.1125081 | S9: =E9/$C9 -> 1.1836502 | T9: =F9/$C9 -> 1.2174622 | U9: =G9/$C9 -> 1.2402277
B10: Cost of sales | C10: 15357 | D10: 18000 | E10: 18520 | F10: 18324 | G10: 18397 | J10: =C10/C$9 -> 0.39728366 | K10: =D10/D$9 -> 0.41856571 | L10: =E10/E$9 -> 0.40477335 | M10: =F10/F$9 -> 0.38936699 | N10: =G10/G$9 -> 0.38374252 | Q10: =C10/$C10 -> 1 | R10: =D10/$C10 -> 1.1721039 | S10: =E10/$C10 -> 1.2059647 | T10: =F10/$C10 -> 1.1932018 | U10: =G10/$C10 -> 1.1979553
B11: Gross Profit | C11: =C9-C10 -> 23298 | D11: =D9-D10 -> 25004 | E11: =E9-E10 -> 27234 | F11: =F9-F10 -> 28737 | G11: =G9-G10 -> 29544 | J11: =C11/C$9 -> 0.60271634 | K11: =D11/D$9 -> 0.58143429 | L11: =E11/E$9 -> 0.59522665 | M11: =F11/F$9 -> 0.61063301 | N11: =G11/G$9 -> 0.61625748 | Q11: =C11/$C11 -> 1 | R11: =D11/$C11 -> 1.0732252 | S11: =E11/$C11 -> 1.1689415 | T11: =F11/$C11 -> 1.2334535 | U11: =G11/$C11 -> 1.2680917
B13: Operating expenses
B14: Selling, general and administrative expenses | C14: 12144 | D14: 12880 | E14: 13972 | F14: 14582 | G14: 14521 | J14: =C14/C$9 -> 0.31416376 | K14: =D14/D$9 -> 0.29950702 | L14: =E14/E$9 -> 0.30537221 | M14: =F14/F$9 -> 0.30985317 | N14: =G14/G$9 -> 0.30289314 | Q14: =C14/$C14 -> 1 | R14: =D14/$C14 -> 1.0606061 | S14: =E14/$C14 -> 1.150527 | T14: =F14/$C14 -> 1.2007576 | U14: =G14/$C14 -> 1.1957345
B15: Other operating charges | C15: 846 | D15: 1215 | E15: 1951 | F15: 4163 | G15: 1261 | J15: =C15/C$9 -> 0.021885914 | K15: =D15/D$9 -> 0.028253186 | L15: =E15/E$9 -> 0.042641081 | M15: =F15/F$9 -> 0.088459659 | N15: =G15/G$9 -> 0.026303164 | Q15: =C15/$C15 -> 1 | R15: =D15/$C15 -> 1.4361702 | S15: =E15/$C15 -> 2.3061466 | T15: =F15/$C15 -> 4.9208038 | U15: =G15/$C15 -> 1.4905437
B16: Total Oper. Exp | C16: =+C14+C15 -> 12990 | D16: =+D14+D15 -> 14095 | E16: =+E14+E15 -> 15923 | F16: =+F14+F15 -> 18745 | G16: =+G14+G15 -> 15782 | J16: =C16/C$9 -> 0.33604967 | K16: =D16/D$9 -> 0.32776021 | L16: =E16/E$9 -> 0.34801329 | M16: =F16/F$9 -> 0.39831283 | N16: =G16/G$9 -> 0.3291963 | Q16: =C16/$C16 -> 1 | R16: =D16/$C16 -> 1.0850654 | S16: =E16/$C16 -> 1.2257891 | T16: =F16/$C16 -> 1.4430331 | U16: =G16/$C16 -> 1.2149346
B18: Operating Income (EBIT) | C18: =C11-C16 -> 10308 | D18: =D11-D16 -> 10909 | E18: =E11-E16 -> 11311 | F18: =F11-F16 -> 9992 | G18: =G11-G16 -> 13762 | J18: =C18/C$9 -> 0.26666667 | K18: =D18/D$9 -> 0.25367408 | L18: =E18/E$9 -> 0.24721336 | M18: =F18/F$9 -> 0.21232018 | N18: =G18/G$9 -> 0.28706118 | Q18: =C18/$C18 -> 1 | R18: =D18/$C18 -> 1.0583042 | S18: =E18/$C18 -> 1.0973031 | T18: =F18/$C18 -> 0.9693442 | U18: =G18/$C18 -> 1.3350795
B19: Interest income | C19: 276 | D19: 449 | E19: 907 | F19: 988 | G19: 786 | J19: =C19/C$9 -> 0.0071400854 | K19: =D19/D$9 -> 0.010440889 | L19: =E19/E$9 -> 0.019823403 | M19: =F19/F$9 -> 0.020994029 | N19: =G19/G$9 -> 0.016395152 | Q19: =C19/$C19 -> 1 | R19: =D19/$C19 -> 1.6268116 | S19: =E19/$C19 -> 3.2862319 | T19: =F19/$C19 -> 3.5797101 | U19: =G19/$C19 -> 2.8478261
B20: Interest expense | C20: 1597 | D20: 882 | E20: 1527 | F20: 1656 | G20: 1654 | J20: =C20/C$9 -> 0.04131419 | K20: =D20/D$9 -> 0.02050972 | L20: =E20/E$9 -> 0.033374131 | M20: =F20/F$9 -> 0.035188373 | N20: =G20/G$9 -> 0.03450074 | Q20: =C20/$C20 -> 1 | R20: =D20/$C20 -> 0.55228554 | S20: =E20/$C20 -> 0.95616781 | T20: =F20/$C20 -> 1.0369443 | U20: =G20/$C20 -> 1.0356919
B21: Equity income (loss) - net | C21: 1438 | D21: 1472 | E21: 1691 | F21: 1770 | G21: 2031 | J21: =C21/C$9 -> 0.03720088 | K21: =D21/D$9 -> 0.034229374 | L21: =E21/E$9 -> 0.036958517 | M21: =F21/F$9 -> 0.037610761 | N21: =G21/G$9 -> 0.042364573 | Q21: =C21/$C21 -> 1 | R21: =D21/$C21 -> 1.0236439 | S21: =E21/$C21 -> 1.1759388 | T21: =F21/$C21 -> 1.2308762 | U21: =G21/$C21 -> 1.4123783
B22: Other income (loss) - net | C22: 2000 | D22: -262 | E22: 570 | F22: 1992 | G22: 1073 | J22: =C22/C$9 -> 0.051739749 | K22: =D22/D$9 -> -0.0060924565 | L22: =E22/E$9 -> 0.012457927 | M22: =F22/F$9 -> 0.042328042 | N22: =G22/G$9 -> 0.022381677 | Q22: =C22/$C22 -> 1 | R22: =D22/$C22 -> -0.131 | S22: =E22/$C22 -> 0.285 | T22: =F22/$C22 -> 0.996 | U22: =G22/$C22 -> 0.5365
B24: Pretax Income | C24: =C18+C19-C20+C21+C22 -> 12425 | D24: =D18+D19-D20+D21+D22 -> 11686 | E24: =E18+E19-E20+E21+E22 -> 12952 | F24: =F18+F19-F20+F21+F22 -> 13086 | G24: =G18+G19-G20+G21+G22 -> 15998 | J24: =C24/C$9 -> 0.32143319 | K24: =D24/D$9 -> 0.27174216 | L24: =E24/E$9 -> 0.28307908 | M24: =F24/F$9 -> 0.27806464 | N24: =G24/G$9 -> 0.33370184 | Q24: =C24/$C24 -> 1 | R24: =D24/$C24 -> 0.94052314 | S24: =E24/$C24 -> 1.0424145 | T24: =F24/$C24 -> 1.0531992 | U24: =G24/$C24 -> 1.2875654
B25: Provision for income taxes | C25: 2621 | D25: 2115 | E25: 2249 | F25: 2437 | G25: 2861 | J25: =C25/C$9 -> 0.067804941 | K25: =D25/D$9 -> 0.049181471 | L25: =E25/E$9 -> 0.049154172 | M25: =F25/F$9 -> 0.051783855 | N25: =G25/G$9 -> 0.05967752 | Q25: =C25/$C25 -> 1 | R25: =D25/$C25 -> 0.80694391 | S25: =E25/$C25 -> 0.85806944 | T25: =F25/$C25 -> 0.92979779 | U25: =G25/$C25 -> 1.0915681
B26: Effective Tax rate | C26: =C25/C24 -> 0.21094567 | D26: =D25/D24 -> 0.18098579 | E26: =E25/E24 -> 0.17364114 | F26: =F25/F24 -> 0.18622956 | G26: =G25/G24 -> 0.17883485 | J26: =C26/C$9 -> 5.4571381e-06 | K26: =D26/D$9 -> 4.2085805e-06 | L26: =E26/E$9 -> 3.7951029e-06 | M26: =F26/F$9 -> 3.9571951e-06 | N26: =G26/G$9 -> 3.7303113e-06 | Q26: =C26/$C26 -> 1 | R26: =D26/$C26 -> 0.85797348 | S26: =E26/$C26 -> 0.82315571 | T26: =F26/$C26 -> 0.88283184 | U26: =G26/$C26 -> 0.84777683
B28: Net income | C28: =C24-C25 -> 9804 | D28: =D24-D25 -> 9571 | E28: =E24-E25 -> 10703 | F28: =F24-F25 -> 10649 | G28: =G24-G25 -> 13137 | J28: =C28/C$9 -> 0.25362825 | K28: =D28/D$9 -> 0.22256069 | L28: =E28/E$9 -> 0.2339249 | M28: =F28/F$9 -> 0.22628078 | N28: =G28/G$9 -> 0.27402432 | Q28: =C28/$C28 -> 1 | R28: =D28/$C28 -> 0.97623419 | S28: =E28/$C28 -> 1.0916973 | T28: =F28/$C28 -> 1.0861893 | U28: =G28/$C28 -> 1.3399633
B30: Number of Shares Outstanding | C30: 4315 | D30: 4328 | E30: 4323 | F30: 4309 | G30: 4303
B31: Stock Price | C31: 59.21 | D31: 63.61 | E31: 58.93 | F31: 62.26 | G31: 69.91
B35: Depreciation and amortization | C35: 1050 | D35: 1075 | E35: 1128 | F35: 1260 | G35: 1452
B36: Dividends Paid | C36: 8779 | D36: 8359 | E36: 7952 | F36: 7616 | G36: 7252
B37: Net Cash Provided by Operating Activities | C37: 7408 | D37: 6805 | E37: 11599 | F37: 11018 | G37: 12625
B38: Purchases of property, plant and equipment | C38: 2112 | D38: 2064 | E38: 1852 | F38: 1484 | G38: 1367
B41: COCA COLA
B42: COMMON SIZING AND TREND ANALYSIS (in 000's Except Per Share Data)
B43: BALANCE SHEET DATA
B44: YOUR NAME | U44: Page 2 of 3
B45: =B5 -> FIN320 Section B
J47: Common-Size Analysis | Q47: Trend Analysis
J48: (as a percentage of total assets) | Q48: (using 2021 as a base year)
B49: Balance Sheet | C49: 2021 | D49: 2022 | E49: 2023 | F49: 2024 | G49: 2025 | J49: 2021 | K49: 2022 | L49: 2023 | M49: 2024 | N49: 2025 | Q49: 2021 | R49: 2022 | S49: 2023 | T49: 2024 | U49: 2025
B50: ASSETS:
B51: Current assets:
...

Sheet CELSIUS (CELH)
B2: COMMON SIZING AND TREND ANALYSIS (in 000's Except Per Share Data)
B3: INCOME STATEMENT DATA
B4: NAME | U4: Page 1 of 3
B5: FIN320 Section B
J6: Common-Size Analysis | Q6: Trend Analysis
J7: (as a percentage of sales) | Q7: (using 2020 as the base year)
B8: Income Statement | C8: 2021 | D8: 2022 | E8: 2023 | F8: 2024 | G8: 2025 | J8: 2021 | K8: 2022 | L8: 2023 | M8: 2024 | N8: 2025 | Q8: 2021 | R8: 2022 | S8: 2023 | T8: 2024 | U8: 2025
B9: Net Operating Revenues | C9: 314272 | D9: 653604 | E9: 1318014 | F9: 1355630 | G9: 2515269 | J9: =C9/C$9 -> 1 | K9: =D9/D$9 -> 1 | L9: =E9/E$9 -> 1 | M9: =F9/F$9 -> 1 | N9: =G9/G$9 -> 1 | Q9: =C9/$C9 -> 1 | R9: =D9/$C9 -> 2.0797398 | S9: =E9/$C9 -> 4.1938639 | T9: =F9/$C9 -> 4.3135564 | U9: =G9/$C9 -> 8.0034779
B10: Cost of sales | C10: 186103 | D10: 382735 | E10: 684875 | F10: 675423 | G10: 1247936 | J10: =C10/C$9 -> 0.59217175 | K10: =D10/D$9 -> 0.58557628 | L10: =E10/E$9 -> 0.5196265 | M10: =F10/F$9 -> 0.49823551 | N10: =G10/G$9 -> 0.49614415 | Q10: =C10/$C10 -> 1 | R10: =D10/$C10 -> 2.0565762 | S10: =E10/$C10 -> 3.6800858 | T10: =F10/$C10 -> 3.6292967 | U10: =G10/$C10 -> 6.70562
B11: Gross Profit | C11: =C9-C10 -> 128169 | D11: =D9-D10 -> 270869 | E11: =E9-E10 -> 633139 | F11: =F9-F10 -> 680207 | G11: =G9-G10 -> 1267333 | J11: =C11/C$9 -> 0.40782825 | K11: =D11/D$9 -> 0.41442372 | L11: =E11/E$9 -> 0.4803735 | M11: =F11/F$9 -> 0.50176449 | N11: =G11/G$9 -> 0.50385585 | Q11: =C11/$C11 -> 1 | R11: =D11/$C11 -> 2.1133737 | S11: =E11/$C11 -> 4.9398763 | T11: =F11/$C11 -> 5.3071101 | U11: =G11/$C11 -> 9.8879838
B13: Operating expenses
B14: Selling, general and administrative expenses | C14: 132259 | D14: 428670 | E14: 366773 | F14: 524479 | G14: 798810 | J14: =C14/C$9 -> 0.42084245 | K14: =D14/D$9 -> 0.65585584 | L14: =E14/E$9 -> 0.27827701 | M14: =F14/F$9 -> 0.38688949 | N14: =G14/G$9 -> 0.31758432 | Q14: =C14/$C14 -> 1 | R14: =D14/$C14 -> 3.2411405 | S14: =E14/$C14 -> 2.7731421 | T14: =F14/$C14 -> 3.9655449 | U14: =G14/$C14 -> 6.0397402
B15: Other operating charges | G15: 327461 | J15: =C15/C$9 -> 0 | K15: =D15/D$9 -> 0 | L15: =E15/E$9 -> 0 | M15: =F15/F$9 -> 0 | N15: =G15/G$9 -> 0.13018926
B16: Total Oper. Exp | C16: =+C14+C15 -> 132259 | D16: =+D14+D15 -> 428670 | E16: =+E14+E15 -> 366773 | F16: =+F14+F15 -> 524479 | G16: =+G14+G15 -> 1126271 | J16: =C16/C$9 -> 0.42084245 | K16: =D16/D$9 -> 0.65585584 | L16: =E16/E$9 -> 0.27827701 | M16: =F16/F$9 -> 0.38688949 | N16: =G16/G$9 -> 0.44777358 | Q16: =C16/$C16 -> 1 | R16: =D16/$C16 -> 3.2411405 | S16: =E16/$C16 -> 2.7731421 | T16: =F16/$C16 -> 3.9655449 | U16: =G16/$C16 -> 8.5156473
B18: Operating Income (EBIT) | C18: =C11-C16 -> -4090 | D18: =D11-D16 -> -157801 | E18: =E11-E16 -> 266366 | F18: =F11-F16 -> 155728 | G18: =G11-G16 -> 141062 | J18: =C18/C$9 -> -0.013014204 | K18: =D18/D$9 -> -0.24143212 | L18: =E18/E$9 -> 0.20209649 | M18: =F18/F$9 -> 0.114875 | N18: =G18/G$9 -> 0.056082272 | Q18: =C18/$C18 -> 1 | R18: =D18/$C18 -> 38.582152 | S18: =E18/$C18 -> -65.126161 | T18: =F18/$C18 -> -38.075306 | U18: =G18/$C18 -> -34.489487
B19: Interest income | C19: 315 | D19: 237 | E19: 26629 | F19: 39263 | G19: 21085 | J19: =C19/C$9 -> 0.0010023165 | K19: =D19/D$9 -> 0.00036260488 | L19: =E19/E$9 -> 0.020203883 | M19: =F19/F$9 -> 0.028962918 | N19: =G19/G$9 -> 0.0083828012 | Q19: =C19/$C19 -> 1 | R19: =D19/$C19 -> 0.75238095 | S19: =E19/$C19 -> 84.536508 | T19: =F19/$C19 -> 124.64444 | U19: =G19/$C19 -> 66.936508
B20: Interest expense | C20: 8 | D20: -5292 | G20: 48977 | J20: =C20/C$9 -> 2.5455656e-05 | K20: =D20/D$9 -> -0.0080966457 | L20: =E20/E$9 -> 0 | M20: =F20/F$9 -> 0 | N20: =G20/G$9 -> 0.019471874 | Q20: =C20/$C20 -> 1 | R20: =D20/$C20 -> -661.5 | S20: =E20/$C20 -> 0 | T20: =F20/$C20 -> 0 | U20: =G20/$C20 -> 6122.125
B21: Equity income (loss) - net | J21: =C21/C$9 -> 0 | K21: =D21/D$9 -> 0 | L21: =E21/E$9 -> 0 | M21: =F21/F$9 -> 0 | N21: =G21/G$9 -> 0
B22: Other income (loss) - net | D22: -392 | E22: -1246 | F22: 59 | G22: 11863 | J22: =C22/C$9 -> 0 | K22: =D22/D$9 -> -0.00059975153 | L22: =E22/E$9 -> -0.00094536173 | M22: =F22/F$9 -> 4.35222e-05 | N22: =G22/G$9 -> 0.0047163942
B24: Pretax Income | C24: =C18+C19-C20+C21+C22 -> -3783 | D24: =D18+D19-D20+D21+D22 -> -152664 | E24: =E18+E19-E20+E21+E22 -> 291749 | F24: =F18+F19-F20+F21+F22 -> 195050 | G24: =G18+G19-G20+G21+G22 -> 125033 | J24: =C24/C$9 -> -0.012037343 | K24: =D24/D$9 -> -0.23357262 | L24: =E24/E$9 -> 0.22135501 | M24: =F24/F$9 -> 0.14388144 | N24: =G24/G$9 -> 0.049709594 | Q24: =C24/$C24 -> 1 | R24: =D24/$C24 -> 40.355274 | S24: =E24/$C24 -> -77.121068 | T24: =F24/$C24 -> -51.559609 | U24: =G24/$C24 -> -33.051282
B25: Provision for income taxes | C25: -7996 | D25: 34618 | E25: 64948 | F25: 49976 | G25: 17034 | J25: =C25/C$9 -> -0.025442928 | K25: =D25/D$9 -> 0.052964792 | L25: =E25/E$9 -> 0.04927717 | M25: =F25/F$9 -> 0.036865516 | N25: =G25/G$9 -> 0.0067722379 | Q25: =C25/$C25 -> 1 | R25: =D25/$C25 -> -4.3294147 | S25: =E25/$C25 -> -8.1225613 | T25: =F25/$C25 -> -6.2501251 | U25: =G25/$C25 -> -2.1303152
B26: Effective Tax rate | C26: =C25/C24 -> 2.1136664 | D26: =D25/D24 -> -0.22675942 | E26: =E25/E24 -> 0.22261602 | F26: =F25/F24 -> 0.25622148 | G26: =G25/G24 -> 0.13623603 | J26: =C26/C$9 -> 6.7255957e-06 | K26: =D26/D$9 -> -3.4693701e-07 | L26: =E26/E$9 -> 1.6890262e-07 | M26: =F26/F$9 -> 1.8900547e-07 | N26: =G26/G$9 -> 5.4163604e-08 | Q26: =C26/$C26 -> 1 | R26: =D26/$C26 -> -0.1072825 | S26: =E26/$C26 -> 0.10532221 | T26: =F26/$C26 -> 0.12122134 | U26: =G26/$C26 -> 0.064454842
B28: Net income | C28: =C24-C25 -> 4213 | D28: =D24-D25 -> -187282 | E28: =E24-E25 -> 226801 | F28: =F24-F25 -> 145074 | G28: =G24-G25 -> 107999 | J28: =C28/C$9 -> 0.013405585 | K28: =D28/D$9 -> -0.28653741 | L28: =E28/E$9 -> 0.17207784 | M28: =F28/F$9 -> 0.10701593 | N28: =G28/G$9 -> 0.042937356 | Q28: =C28/$C28 -> 1 | R28: =D28/$C28 -> -44.453359 | S28: =E28/$C28 -> 53.83361 | T28: =F28/$C28 -> 34.434845 | U28: =G28/$C28 -> 25.634702
B30: Number of Shares Outstanding | C30: =74909000/1000 -> 74909 | D30: =76382000/1000 -> 76382 | E30: =231787482/1000 -> 231787.48 | F30: =235014000/1000 -> 235014 | G30: =256906000/1000 -> 256906
B31: Stock Price | C31: 24.86 | D31: 34.68 | E31: 54.52 | F31: 26.34 | G31: 45.74
B35: Depreciation and amortization | C35: ='Celsius Holdings, Inc.'!B104 -> 1264 | D35: ='Celsius Holdings, Inc.'!C104 -> 1917 | E35: ='Celsius Holdings, Inc.'!D104 -> 3226 | F35: ='Celsius Holdings, Inc.'!E104 -> 7274 | G35: ='Celsius Holdings, Inc.'!F104 -> 29451
B36: Dividends Paid
B37: Net Cash Provided by Operating Activities
B38: Purchases of property, plant and equipment
B41: CELSIUS
B42: COMMON SIZING AND TREND ANALYSIS (in 000's Except Per Share Data)
B43: BALANCE SHEET DATA
B44: YOUR NAME | U44: Page 2 of 3
B45: =B5 -> FIN320 Section B
J47: Common-Size Analysis | Q47: Trend Analysis
J48: (as a percentage of total assets) | Q48: (using 2021 as a base year)
B49: Balance Sheet | C49: 2021 | D49: 2022 | E49: 2023 | F49: 2024 | G49: 2025 | J49: 2021 | K49: 2022 | L49: 2023 | M49: 2024 | N49: 2025 | Q49: 2021 | R49: 2022 | S49: 2023 | T49: 2024 | U49: 2025
B50: ASSETS:
B51: Current assets:
B52: Cash/Cash equivalents | C52: 16255 | D52: 614159 | E52: 755981 | F52: 890190 | G52: 398866 | J52: =C52/C$67 -> 0.051764549 | K52: =D52/D$67 -> 0.50255673 | L52: =E52/E$67 -> 0.49204827 | M52: =F52/F$67 -> 0.50382001 | N52: =G52/G$67 -> 0.077909283 | Q52: =C52/$C52 -> 1 | R52: =D52/$C52 -> 37.782775 | S52: =E52/$C52 -> 46.507598 | T52: =F52/$C52 -> 54.764073 | U52: =G52/$C52 -> 24.53805
...

Sheet K.Dr Paper (KDP)
B1: DR. PEPPER
B2: COMMON SIZING AND TREND ANALYSIS (in 000's Except Per Share Data)
B3: INCOME STATEMENT DATA
B4: NAME | U4: Page 1 of 3
B5: FIN320 Section B
J6: Common-Size Analysis | Q6: Trend Analysis
J7: (as a percentage of sales) | Q7: (using 2020 as the base year)
B8: Income Statement | C8: 2021 | D8: 2022 | E8: 2023 | F8: 2024 | G8: 2025 | J8: 2021 | K8: 2022 | L8: 2023 | M8: 2024 | N8: 2025 | Q8: 2021 | R8: 2022 | S8: 2023 | T8: 2024 | U8: 2025
B9: Net Operating Revenues | C9: 12683 | D9: 14057 | E9: 14814 | F9: 15351 | G9: 16603 | J9: =C9/C$9 -> 1 | K9: =D9/D$9 -> 1 | L9: =E9/E$9 -> 1 | M9: =F9/F$9 -> 1 | N9: =G9/G$9 -> 1 | Q9: =C9/$C9 -> 1 | R9: =D9/$C9 -> 1.108334 | S9: =E9/$C9 -> 1.1680202 | T9: =F9/$C9 -> 1.2103603 | U9: =G9/$C9 -> 1.3090751
B10: Cost of sales | C10: 5706 | D10: 6734 | E10: 6734 | F10: 6822 | G10: 7604 | J10: =C10/C$9 -> 0.44989356 | K10: =D10/D$9 -> 0.47904958 | L10: =E10/E$9 -> 0.45457 | M10: =F10/F$9 -> 0.44440102 | N10: =G10/G$9 -> 0.45798952 | Q10: =C10/$C10 -> 1 | R10: =D10/$C10 -> 1.1801612 | S10: =E10/$C10 -> 1.1801612 | T10: =F10/$C10 -> 1.1955836 | U10: =G10/$C10 -> 1.3326323
B11: Gross Profit | C11: =C9-C10 -> 6977 | D11: =D9-D10 -> 7323 | E11: =E9-E10 -> 8080 | F11: =F9-F10 -> 8529 | G11: =G9-G10 -> 8999 | J11: =C11/C$9 -> 0.55010644 | K11: =D11/D$9 -> 0.52095042 | L11: =E11/E$9 -> 0.54543 | M11: =F11/F$9 -> 0.55559898 | N11: =G11/G$9 -> 0.54201048 | Q11: =C11/$C11 -> 1 | R11: =D11/$C11 -> 1.0495915 | S11: =E11/$C11 -> 1.1580909 | T11: =F11/$C11 -> 1.2224452 | U11: =G11/$C11 -> 1.2898094
B13: Operating expenses
B14: Selling, general and administrative expenses | C14: 3765 | D14: 4283 | E14: 4488 | F14: 4525 | G14: 4874 | J14: =C14/C$9 -> 0.29685406 | K14: =D14/D$9 -> 0.30468806 | L14: =E14/E$9 -> 0.30295666 | M14: =F14/F$9 -> 0.29476907 | N14: =G14/G$9 -> 0.2935614 | Q14: =C14/$C14 -> 1 | R14: =D14/$C14 -> 1.137583 | S14: =E14/$C14 -> 1.1920319 | T14: =F14/$C14 -> 1.2018592 | U14: =G14/$C14 -> 1.2945551
B15: Other operating charges | C15: 183 | D15: 166 | E15: 365 | F15: 608 | G15: 413 | J15: =C15/C$9 -> 0.014428763 | K15: =D15/D$9 -> 0.011809063 | L15: =E15/E$9 -> 0.024638855 | M15: =F15/F$9 -> 0.03960654 | N15: =G15/G$9 -> 0.024875023 | Q15: =C15/$C15 -> 1 | R15: =D15/$C15 -> 0.90710383 | S15: =E15/$C15 -> 1.9945355 | T15: =F15/$C15 -> 3.3224044 | U15: =G15/$C15 -> 2.2568306
B16: Total Oper. Exp | C16: =+C14+C15 -> 3948 | D16: =+D14+D15 -> 4449 | E16: =+E14+E15 -> 4853 | F16: =+F14+F15 -> 5133 | G16: =+G14+G15 -> 5287 | J16: =C16/C$9 -> 0.31128282 | K16: =D16/D$9 -> 0.31649712 | L16: =E16/E$9 -> 0.32759552 | M16: =F16/F$9 -> 0.33437561 | N16: =G16/G$9 -> 0.31843643 | Q16: =C16/$C16 -> 1 | R16: =D16/$C16 -> 1.1268997 | S16: =E16/$C16 -> 1.22923 | T16: =F16/$C16 -> 1.300152 | U16: =G16/$C16 -> 1.3391591
B18: Operating Income (EBIT) | C18: =C11-C16 -> 3029 | D18: =D11-D16 -> 2874 | E18: =E11-E16 -> 3227 | F18: =F11-F16 -> 3396 | G18: =G11-G16 -> 3712 | J18: =C18/C$9 -> 0.23882362 | K18: =D18/D$9 -> 0.2044533 | L18: =E18/E$9 -> 0.21783448 | M18: =F18/F$9 -> 0.22122337 | N18: =G18/G$9 -> 0.22357405 | Q18: =C18/$C18 -> 1 | R18: =D18/$C18 -> 0.948828 | S18: =E18/$C18 -> 1.0653681 | T18: =F18/$C18 -> 1.1211621 | U18: =G18/$C18 -> 1.225487
B19: Interest income | J19: =C19/C$9 -> 0 | K19: =D19/D$9 -> 0 | L19: =E19/E$9 -> 0 | M19: =F19/F$9 -> 0 | N19: =G19/G$9 -> 0
B20: Interest expense | C20: 500 | D20: 693 | E20: 496 | F20: 735 | G20: 754 | J20: =C20/C$9 -> 0.039422849 | K20: =D20/D$9 -> 0.049299281 | L20: =E20/E$9 -> 0.033481842 | M20: =F20/F$9 -> 0.047879617 | N20: =G20/G$9 -> 0.045413479 | Q20: =C20/$C20 -> 1 | R20: =D20/$C20 -> 1.386 | S20: =E20/$C20 -> 0.992 | T20: =F20/$C20 -> 1.47 | U20: =G20/$C20 -> 1.508
B21: Equity income (loss) - net | C21: -5 | D21: -5 | E21: 33 | F21: 42 | G21: 81 | J21: =C21/C$9 -> -0.00039422849 | K21: =D21/D$9 -> -0.00035569467 | L21: =E21/E$9 -> 0.0022276225 | M21: =F21/F$9 -> 0.0027359781 | N21: =G21/G$9 -> 0.0048786364 | Q21: =C21/$C21 -> 1 | R21: =D21/$C21 -> 1 | S21: =E21/$C21 -> -6.6 | T21: =F21/$C21 -> -8.4 | U21: =G21/$C21 -> -16.2
B22: Other income (loss) - net | C22: 274 | D22: -457 | E22: -7 | F22: -789 | G22: -352 | J22: =C22/C$9 -> 0.021603722 | K22: =D22/D$9 -> -0.032510493 | L22: =E22/E$9 -> -0.00047252599 | M22: =F22/F$9 -> -0.051397303 | N22: =G22/G$9 -> -0.021200988 | Q22: =C22/$C22 -> 1 | R22: =D22/$C22 -> -1.6678832 | S22: =E22/$C22 -> -0.025547445 | T22: =F22/$C22 -> -2.879562 | U22: =G22/$C22 -> -1.2846715
B24: Pretax Income | C24: =C18+C19-C20+C21+C22 -> 2798 | D24: =D18+D19-D20+D21+D22 -> 1719 | E24: =E18+E19-E20+E21+E22 -> 2757 | F24: =F18+F19-F20+F21+F22 -> 1914 | G24: =G18+G19-G20+G21+G22 -> 2687 | J24: =C24/C$9 -> 0.22061027 | K24: =D24/D$9 -> 0.12228783 | L24: =E24/E$9 -> 0.18610774 | M24: =F24/F$9 -> 0.12468243 | N24: =G24/G$9 -> 0.16183822 | Q24: =C24/$C24 -> 1 | R24: =D24/$C24 -> 0.61436741 | S24: =E24/$C24 -> 0.98534668 | T24: =F24/$C24 -> 0.68406004 | U24: =G24/$C24 -> 0.96032881
B25: Provision for income taxes | C25: 653 | D25: 284 | E25: 576 | F25: 473 | G25: 608 | J25: =C25/C$9 -> 0.051486241 | K25: =D25/D$9 -> 0.020203457 | L25: =E25/E$9 -> 0.038882139 | M25: =F25/F$9 -> 0.030812325 | N25: =G25/G$9 -> 0.036619888 | Q25: =C25/$C25 -> 1 | R25: =D25/$C25 -> 0.43491577 | S25: =E25/$C25 -> 0.8820827 | T25: =F25/$C25 -> 0.72434916 | U25: =G25/$C25 -> 0.93108729
B26: Effective Tax rate | C26: =C25/C24 -> 0.23338099 | D26: =D25/D24 -> 0.16521233 | E26: =E25/E24 -> 0.20892274 | F26: =F25/F24 -> 0.24712644 | G26: =G25/G24 -> 0.22627466 | J26: =C26/C$9 -> 1.8401087e-05 | K26: =D26/D$9 -> 1.1753029e-05 | L26: =E26/E$9 -> 1.4103061e-05 | M26: =F26/F$9 -> 1.6098393e-05 | N26: =G26/G$9 -> 1.362854e-05 | Q26: =C26/$C26 -> 1 | R26: =D26/$C26 -> 0.70790828 | S26: =E26/$C26 -> 0.89520036 | T26: =F26/$C26 -> 1.058897 | U26: =G26/$C26 -> 0.96955052
B28: Net income | C28: =C24-C25 -> 2145 | D28: =D24-D25 -> 1435 | E28: =E24-E25 -> 2181 | F28: =F24-F25 -> 1441 | G28: =G24-G25 -> 2079 | J28: =C28/C$9 -> 0.16912402 | K28: =D28/D$9 -> 0.10208437 | L28: =E28/E$9 -> 0.1472256 | M28: =F28/F$9 -> 0.093870106 | N28: =G28/G$9 -> 0.12521833 | Q28: =C28/$C28 -> 1 | R28: =D28/$C28 -> 0.66899767 | S28: =E28/$C28 -> 1.0167832 | T28: =F28/$C28 -> 0.67179487 | U28: =G28/$C28 -> 0.96923077
B30: Number of Shares Outstanding | C30: =KDP!B45 -> 1415.7 | D30: =KDP!C45 -> 1416.8 | E30: =KDP!D45 -> 1399.3 | F30: =KDP!E45 -> 1362.2 | G30: =KDP!F45 -> 1358.1
B31: Stock Price | C31: =KDP!B101 -> 29 | D31: =KDP!C101 -> 36 | E31: =KDP!D101 -> 32 | F31: =KDP!E101 -> 32 | G31: =KDP!F101 -> 28
B35: Depreciation and amortization | C35: =KDP!B18 -> 177 | D35: =KDP!C18 -> 170 | E35: =KDP!D18 -> 171 | F35: =KDP!E18 -> 188 | G35: =KDP!F18 -> 209
B36: Dividends Paid
B37: Net Cash Provided by Operating Activities
B38: Purchases of property, plant and equipment
B41: DR. PEPPER
B42: COMMON SIZING AND TREND ANALYSIS (in 000's Except Per Share Data)
B43: BALANCE SHEET DATA
B44: YOUR NAME | U44: Page 2 of 3
B45: =B5 -> FIN320 Section B
J47: Common-Size Analysis | Q47: Trend Analysis
J48: (as a percentage of total assets) | Q48: (using 2021 as a base year)
B49: Balance Sheet | C49: 2021 | D49: 2022 | E49: 2023 | F49: 2024 | G49: 2025 | J49: 2021 | K49: 2022 | L49: 2023 | M49: 2024 | N49: 2025 | Q49: 2021 | R49: 2022 | S49: 2023 | T49: 2024 | U49: 2025
B50: ASSETS:
B51: Current assets:
...

Sheet KDP
A1: Keurig's Dr Pepper
A2: COMMON SIZING AND TREND ANALYSIS (in millions Except Per Share Data)
A3: INCOME STATEMENT DATA
A4: NAME: Neeha Pyneni | B4: Template: | C4: Standard | E4: Restatement: | F4: Latest Filings | T4: Page 1 of 3
A5: FIN320 Section B | B5: Period Type: | C5: Annual | E5: Order: | F5: Latest on Right
B6: Currency: | C6: Reported Currency | E6: Conversion: | F6: Historical
B7: Units: | C7: S&P Capital IQ (Default) | E7: Decimals: | F7: Capital IQ (Default)
B8: Source: | C8: Capital IQ & Proprietary Data | I8: Common-Size Analysis | P8: Trend Analysis
I9: (as a percentage of sales) | P9: (using 2020 as the base year)
A10: Income Statement | B10: 2021 | C10: 2022 | D10: 2023 | E10: 2024 | F10: 2025 | I10: 2021 | J10: 2022 | K10: 2023 | L10: 2024 | M10: 2025 | P10: 2021 | Q10: 2022 | R10: 2023 | S10: 2024 | T10: 2025
A12: Revenue | B12: 12683 | C12: 14057 | D12: 14814 | E12: 15351 | F12: 16603 | I12: =B12/$B$12 -> 1 | J12: =C12/$C$12 -> 1 | K12: =D12/$D$12 -> 1 | L12: =E12/$E$12 -> 1 | M12: =F12/$F$12 -> 1 | P12: =B12/$B12 -> 1 | Q12: =C12/$B12 -> 1.108334 | R12: =D12/$B12 -> 1.1680202 | S12: =E12/$B12 -> 1.2103603 | T12: =F12/$B12 -> 1.3090751
A13: Total Revenue | B13: 12683 | C13: 14057 | D13: 14814 | E13: 15351 | F13: 16603 | I13: =B13/$B$12 -> 1 | J13: =C13/$C$12 -> 1 | K13: =D13/$D$12 -> 1 | L13: =E13/$E$12 -> 1 | M13: =F13/$F$12 -> 1 | P13: =B13/$B13 -> 1 | Q13: =C13/$B13 -> 1.108334 | R13: =D13/$B13 -> 1.1680202 | S13: =E13/$B13 -> 1.2103603 | T13: =F13/$B13 -> 1.3090751
A14: Cost Of Goods Sold | B14: 5706 | C14: 6734 | D14: 6734 | E14: 6822 | F14: 7604 | I14: =B14/$B$12 -> 0.44989356 | J14: =C14/$C$12 -> 0.47904958 | K14: =D14/$D$12 -> 0.45457 | L14: =E14/$E$12 -> 0.44440102 | M14: =F14/$F$12 -> 0.45798952 | P14: =B14/$B14 -> 1 | Q14: =C14/$B14 -> 1.1801612 | R14: =D14/$B14 -> 1.1801612 | S14: =E14/$B14 -> 1.1955836 | T14: =F14/$B14 -> 1.3326323
A15: Gross Profit | B15: 6977 | C15: 7323 | D15: 8080 | E15: 8529 | F15: 8999 | I15: =B15/$B$12 -> 0.55010644 | J15: =C15/$C$12 -> 0.52095042 | K15: =D15/$D$12 -> 0.54543 | L15: =E15/$E$12 -> 0.55559898 | M15: =F15/$F$12 -> 0.54201048 | P15: =B15/$B15 -> 1 | Q15: =C15/$B15 -> 1.0495915 | R15: =D15/$B15 -> 1.1580909 | S15: =E15/$B15 -> 1.2224452 | T15: =F15/$B15 -> 1.2898094
A16: Selling General & Admin Exp. | B16: 3765 | C16: 4283 | D16: 4488 | E16: 4525 | F16: 4874 | I16: =B16/$B$12 -> 0.29685406 | J16: =C16/$C$12 -> 0.30468806 | K16: =D16/$D$12 -> 0.30295666 | L16: =E16/$E$12 -> 0.29476907 | M16: =F16/$F$12 -> 0.2935614 | P16: =B16/$B16 -> 1 | Q16: =C16/$B16 -> 1.137583 | R16: =D16/$B16 -> 1.1920319 | S16: =E16/$B16 -> 1.2018592 | T16: =F16/$B16 -> 1.2945551
A17: R & D Exp. | B17: 66 | C17: 65 | D17: 66 | E17: 70 | F17: 70 | I17: =B17/$B$12 -> 0.0052038161 | J17: =C17/$C$12 -> 0.0046240307 | K17: =D17/$D$12 -> 0.004455245 | L17: =E17/$E$12 -> 0.0045599635 | M17: =F17/$F$12 -> 0.0042161055 | P17: =B17/$B17 -> 1 | Q17: =C17/$B17 -> 0.98484848 | R17: =D17/$B17 -> 1 | S17: =E17/$B17 -> 1.0606061 | T17: =F17/$B17 -> 1.0606061
A18: Depreciation & Amort. | B18: 177 | C18: 170 | D18: 171 | E18: 188 | F18: 209 | I18: =B18/$B$12 -> 0.013955689 | J18: =C18/$C$12 -> 0.012093619 | K18: =D18/$D$12 -> 0.011543135 | L18: =E18/$E$12 -> 0.012246759 | M18: =F18/$F$12 -> 0.012588086 | P18: =B18/$B18 -> 1 | Q18: =C18/$B18 -> 0.96045198 | R18: =D18/$B18 -> 0.96610169 | S18: =E18/$B18 -> 1.0621469 | T18: =F18/$B18 -> 1.180791
A19: Amort. of Goodwill and Intangibles | B19: - | C19: - | D19: 137 | E19: 133 | F19: 138 | K19: =D19/$D$12 -> 0.0092480086 | L19: =E19/$E$12 -> 0.0086639307 | M19: =F19/$F$12 -> 0.0083117509
A20: Other Operating Expense/(Income) | B20: -60 | C20: -69 | D20: -9 | E20: 217 | F20: -4 | I20: =B20/$B$12 -> -0.0047307419 | J20: =C20/$C$12 -> -0.0049085865 | K20: =D20/$D$12 -> -0.00060753341 | L20: =E20/$E$12 -> 0.014135887 | M20: =F20/$F$12 -> -0.00024092032 | P20: =B20/$B20 -> 1 | Q20: =C20/$B20 -> 1.15 | R20: =D20/$B20 -> 0.15 | S20: =E20/$B20 -> -3.6166667 | T20: =F20/$B20 -> 0.066666667
A21: Other Operating Exp., Total | B21: 3948 | C21: 4449 | D21: 4853 | E21: 5133 | F21: 5287 | I21: =B21/$B$12 -> 0.31128282 | J21: =C21/$C$12 -> 0.31649712 | K21: =D21/$D$12 -> 0.32759552 | L21: =E21/$E$12 -> 0.33437561 | M21: =F21/$F$12 -> 0.31843643 | P21: =B21/$B21 -> 1 | Q21: =C21/$B21 -> 1.1268997 | R21: =D21/$B21 -> 1.22923 | S21: =E21/$B21 -> 1.300152 | T21: =F21/$B21 -> 1.3391591
A22: Operating Income | B22: 3029 | C22: 2874 | D22: 3227 | E22: 3396 | F22: 3712 | I22: =B22/$B$12 -> 0.23882362 | J22: =C22/$C$12 -> 0.2044533 | K22: =D22/$D$12 -> 0.21783448 | L22: =E22/$E$12 -> 0.22122337 | M22: =F22/$F$12 -> 0.22357405 | P22: =B22/$B22 -> 1 | Q22: =C22/$B22 -> 0.948828 | R22: =D22/$B22 -> 1.0653681 | S22: =E22/$B22 -> 1.1211621 | T22: =F22/$B22 -> 1.225487
A23: Interest Expense | B23: -500 | C23: -693 | D23: -496 | E23: -735 | F23: -754 | I23: =B23/$B$12 -> -0.039422849 | J23: =C23/$C$12 -> -0.049299281 | K23: =D23/$D$12 -> -0.033481842 | L23: =E23/$E$12 -> -0.047879617 | M23: =F23/$F$12 -> -0.045413479 | P23: =B23/$B23 -> 1 | Q23: =C23/$B23 -> 1.386 | R23: =D23/$B23 -> 0.992 | S23: =E23/$B23 -> 1.47 | T23: =F23/$B23 -> 1.508
A24: Income/(Loss) from Affiliates | B24: -5 | C24: -5 | D24: 33 | E24: 42 | F24: 81 | I24: =B24/$B$12 -> -0.00039422849 | J24: =C24/$C$12 -> -0.00035569467 | K24: =D24/$D$12 -> 0.0022276225 | L24: =E24/$E$12 -> 0.0027359781 | M24: =F24/$F$12 -> 0.0048786364 | P24: =B24/$B24 -> 1 | Q24: =C24/$B24 -> 1 | R24: =D24/$B24 -> -6.6 | S24: =E24/$B24 -> -8.4 | T24: =F24/$B24 -> -16.2
A25: Currency Exchange Gains (Loss) | B25: - | C25: 9 | D25: -5 | E25: 10 | F25: -36 | J25: =C25/$C$12 -> 0.00064025041 | K25: =D25/$D$12 -> -0.00033751856 | L25: =E25/$E$12 -> 0.00065142336 | M25: =F25/$F$12 -> -0.0021682828
A26: Other Non-Operating Inc. (Exp.) | B26: 4 | C26: -19 | D26: 35 | E26: 10 | F26: -175 | I26: =B26/$B$12 -> 0.0003153828 | J26: =C26/$C$12 -> -0.0013516398 | K26: =D26/$D$12 -> 0.0023626299 | L26: =E26/$E$12 -> 0.00065142336 | M26: =F26/$F$12 -> -0.010540264 | P26: =B26/$B26 -> 1 | Q26: =C26/$B26 -> -4.75 | R26: =D26/$B26 -> 8.75 | S26: =E26/$B26 -> 2.5 | T26: =F26/$B26 -> -43.75
A27: EBT Excl. Unusual Items | B27: 2528 | C27: 2166 | D27: 2794 | E27: 2723 | F27: 2828 | I27: =B27/$B$12 -> 0.19932193 | J27: =C27/$C$12 -> 0.15408693 | K27: =D27/$D$12 -> 0.18860537 | L27: =E27/$E$12 -> 0.17738258 | M27: =F27/$F$12 -> 0.17033066 | P27: =B27/$B27 -> 1 | Q27: =C27/$B27 -> 0.8568038 | R27: =D27/$B27 -> 1.1052215 | S27: =E27/$B27 -> 1.0771361 | T27: =F27/$B27 -> 1.1186709
A28: Merger & Related Restruct. Charges | B28: -202 | C28: -172 | D28: -35 | E28: -91 | F28: -63 | I28: =B28/$B$12 -> -0.015926831 | J28: =C28/$C$12 -> -0.012235897 | K28: =D28/$D$12 -> -0.0023626299 | L28: =E28/$E$12 -> -0.0059279526 | M28: =F28/$F$12 -> -0.003794495 | P28: =B28/$B28 -> 1 | Q28: =C28/$B28 -> 0.85148515 | R28: =D28/$B28 -> 0.17326733 | S28: =E28/$B28 -> 0.45049505 | T28: =F28/$B28 -> 0.31188119
A29: Impairment of Goodwill | B29: - | C29: - | D29: - | E29: -306 | F29: - | L29: =E29/$E$12 -> -0.019933555
A30: Gain (Loss) On Sale Of Invest. | B30: 507 | C30: 38 | D30: - | E30: - | F30: - | I30: =B30/$B$12 -> 0.039974769 | J30: =C30/$C$12 -> 0.0027032795 | P30: =B30/$B30 -> 1 | Q30: =C30/$B30 -> 0.07495069
A31: Gain (Loss) On Sale Of Assets | B31: 70 | C31: 82 | D31: - | E31: - | F31: - | I31: =B31/$B$12 -> 0.0055191989 | J31: =C31/$C$12 -> 0.0058333926 | P31: =B31/$B31 -> 1 | Q31: =C31/$B31 -> 1.1714286
A32: Asset Writedown | B32: - | C32: -477 | D32: -2 | E32: -412 | F32: -78 | J32: =C32/$C$12 -> -0.033933272 | K32: =D32/$D$12 -> -0.00013500743 | L32: =E32/$E$12 -> -0.026838642 | M32: =F32/$F$12 -> -0.0046979462
A33: Legal Settlements | B33: - | C33: 299 | D33: - | E33: - | F33: - | J33: =C33/$C$12 -> 0.021270541
A34: Other Unusual Items | B34: -105 | C34: -217 | D34: - | E34: - | F34: - | I34: =B34/$B$12 -> -0.0082787984 | J34: =C34/$C$12 -> -0.015437149 | P34: =B34/$B34 -> 1 | Q34: =C34/$B34 -> 2.0666667
A35: EBT Incl. Unusual Items | B35: 2798 | C35: 1719 | D35: 2757 | E35: 1914 | F35: 2687 | I35: =B35/$B$12 -> 0.22061027 | J35: =C35/$C$12 -> 0.12228783 | K35: =D35/$D$12 -> 0.18610774 | L35: =E35/$E$12 -> 0.12468243 | M35: =F35/$F$12 -> 0.16183822 | P35: =B35/$B35 -> 1 | Q35: =C35/$B35 -> 0.61436741 | R35: =D35/$B35 -> 0.98534668 | S35: =E35/$B35 -> 0.68406004 | T35: =F35/$B35 -> 0.96032881
A36: Income Tax Expense | B36: 653 | C36: 284 | D36: 576 | E36: 473 | F36: 608 | I36: =B36/$B$12 -> 0.051486241 | J36: =C36/$C$12 -> 0.020203457 | K36: =D36/$D$12 -> 0.038882139 | L36: =E36/$E$12 -> 0.030812325 | M36: =F36/$F$12 -> 0.036619888 | P36: =B36/$B36 -> 1 | Q36: =C36/$B36 -> 0.43491577 | R36: =D36/$B36 -> 0.8820827 | S36: =E36/$B36 -> 0.72434916 | T36: =F36/$B36 -> 0.93108729
A37: Earnings from Cont. Ops. | B37: 2145 | C37: 1435 | D37: 2181 | E37: 1441 | F37: 2079 | I37: =B37/$B$12 -> 0.16912402 | J37: =C37/$C$12 -> 0.10208437 | K37: =D37/$D$12 -> 0.1472256 | L37: =E37/$E$12 -> 0.093870106 | M37: =F37/$F$12 -> 0.12521833 | P37: =B37/$B37 -> 1 | Q37: =C37/$B37 -> 0.66899767 | R37: =D37/$B37 -> 1.0167832 | S37: =E37/$B37 -> 0.67179487 | T37: =F37/$B37 -> 0.96923077
A38: Net Income to Company | B38: 2145 | C38: 1435 | D38: 2181 | E38: 1441 | F38: 2079 | I38: =B38/$B$12 -> 0.16912402 | J38: =C38/$C$12 -> 0.10208437 | K38: =D38/$D$12 -> 0.1472256 | L38: =E38/$E$12 -> 0.093870106 | M38: =F38/$F$12 -> 0.12521833 | P38: =B38/$B38 -> 1 | Q38: =C38/$B38 -> 0.66899767 | R38: =D38/$B38 -> 1.0167832 | S38: =E38/$B38 -> 0.67179487 | T38: =F38/$B38 -> 0.96923077
A39: Minority Int. in Earnings | B39: 1 | C39: 1 | D39: - | E39: - | F39: - | I39: =B39/$B$12 -> 7.8845699e-05 | J39: =C39/$C$12 -> 7.1138934e-05 | P39: =B39/$B39 -> 1 | Q39: =C39/$B39 -> 1
A40: Net Income | B40: 2146 | C40: 1436 | D40: 2181 | E40: 1441 | F40: 2079 | I40: =B40/$B$12 -> 0.16920287 | J40: =C40/$C$12 -> 0.10215551 | K40: =D40/$D$12 -> 0.1472256 | L40: =E40/$E$12 -> 0.093870106 | M40: =F40/$F$12 -> 0.12521833 | P40: =B40/$B40 -> 1 | Q40: =C40/$B40 -> 0.66915191 | R40: =D40/$B40 -> 1.0163094 | S40: =E40/$B40 -> 0.67148183 | T40: =F40/$B40 -> 0.96877912
A41: NI to Common Incl Extra Items | B41: 2146 | C41: 1436 | D41: 2181 | E41: 1441 | F41: 2079 | I41: =B41/$B$12 -> 0.16920287 | J41: =C41/$C$12 -> 0.10215551 | K41: =D41/$D$12 -> 0.1472256 | L41: =E41/$E$12 -> 0.093870106 | M41: =F41/$F$12 -> 0.12521833 | P41: =B41/$B41 -> 1 | Q41: =C41/$B41 -> 0.66915191 | R41: =D41/$B41 -> 1.0163094 | S41: =E41/$B41 -> 0.67148183 | T41: =F41/$B41 -> 0.96877912
...

Sheet Celsius Holdings, Inc.
A1: Celsius Holdings, INC.
A2: COMMON SIZING AND TREND ANALYSIS (in 000's Except Per Share Data)
A3: BALANCE SHEET STATEMENT DATA
A5: CELH Balance Sheet ($ in thousands) | H5: Common size Balance sheet | N5: Trend Analysis
A6: Line Item | B6: 2021 | C6: 2022 | D6: 2023 | E6: 2024 | F6: 2025 | H6: 2021 | I6: 2022 | J6: 2023 | K6: 2024 | L6: 2025 | N6: 2021 | O6: 2022 | P6: 2023 | Q6: 2024 | R6: 2025
A7: ASSETS
A8: Current assets
A9: Cash and cash equivalents | B9: 16255 | C9: 614159 | D9: 755981 | E9: 890190 | F9: 398866 | H9: =B9/$B$31 -> 0.051764549 | I9: =C9/$C$31 -> 0.50255673 | J9: =D9/$D$31 -> 0.49204827 | K9: =E9/$E$31 -> 0.50382001 | L9: =F9/$F$31 -> 0.077909283 | N9: =B9/$B9 -> 1 | O9: =C9/$B9 -> 37.782775 | P9: =D9/$B9 -> 46.507598 | Q9: =E9/$B9 -> 54.764073 | R9: =F9/$B9 -> 24.53805
A10: Accounts receivable-net | B10: 38741 | C10: 63311 | D10: 183703 | E10: 270342 | F10: 755499 | H10: =B10/$B$31 -> 0.12337191 | I10: =C10/$C$31 -> 0.051806404 | J10: =D10/$D$31 -> 0.11956748 | K10: =E10/$E$31 -> 0.15300521 | L10: =F10/$F$31 -> 0.14756932 | N10: =B10/$B10 -> 1 | O10: =C10/$B10 -> 1.6342118 | P10: =D10/$B10 -> 4.7418239 | Q10: =E10/$B10 -> 6.9781885 | R10: =F10/$B10 -> 19.501278
A11: Inventories-net | B11: 191222 | C11: 173289 | D11: 229275 | E11: 131165 | F11: 337698 | H11: =B11/$B$31 -> 0.60895235 | I11: =C11/$C$31 -> 0.14179969 | J11: =D11/$D$31 -> 0.1492291 | K11: =E11/$E$31 -> 0.074235333 | L11: =F11/$F$31 -> 0.065961523 | N11: =B11/$B11 -> 1 | O11: =C11/$B11 -> 0.90621895 | P11: =D11/$B11 -> 1.1989991 | Q11: =E11/$B11 -> 0.68593049 | R11: =F11/$B11 -> 1.7659997
A13: Other current assets | B13: 16143 | C13: 67212 | D13: 35945 | E13: 32883 | F13: 319091 | H13: =B13/$B$31 -> 0.051407881 | I13: =C13/$C$31 -> 0.054998531 | J13: =D13/$D$31 -> 0.023395661 | K13: =E13/$E$31 -> 0.018610761 | L13: =F13/$F$31 -> 0.062327075 | N13: =B13/$B13 -> 1 | O13: =C13/$B13 -> 4.1635384 | P13: =D13/$B13 -> 2.2266617 | Q13: =E13/$B13 -> 2.036982 | R13: =F13/$B13 -> 19.766524
A14: Restricted cash | B14: 0 | C14: 38768 | D14: 0 | E14: 0 | F14: 141121 | H14: 0 | I14: =C14/$C$31 -> 0.03172325 | J14: 0 | K14: 0 | L14: =F14/$F$31 -> 0.027564736 | N14: N/A | O14: =C14/C14 -> 1 | P14: N/A | Q14: N/A | R14: =F14/C14 -> 3.6401414
A15: Note receivable-current | B15: 2588 | C15: 2979 | D15: 2318 | E15: 0 | F15: 0 | H15: =B15/$B$31 -> 0.0082415658 | I15: =C15/$C$31 -> 0.0024376692 | J15: =D15/$D$31 -> 0.0015087256 | K15: 0 | L15: 0 | N15: =B15/$B15 -> 1 | O15: =C15/$B15 -> 1.1510819 | P15: =D15/$B15 -> 0.89567233 | Q15: N/A | R15: N/A
A16: Prepaid expenses and other current assets | B16: 13555 | C16: 11341 | D16: 19503 | E16: 18759 | F16: 128806 | H16: =B16/$B$31 -> 0.043166315 | I16: =C16/$C$31 -> 0.0092801634 | J16: =D16/$D$31 -> 0.012693993 | K16: =E16/$E$31 -> 0.010617014 | L16: =F16/$F$31 -> 0.025159284 | N16: =B16/$B16 -> 1 | O16: =C16/$B16 -> 0.83666544 | P16: =D16/$B16 -> 1.4388049 | Q16: =E16/$B16 -> 1.3839174 | R16: =F16/$B16 -> 9.5024714
