Workbook

Sheet Cover letter
B2: Church & Dwight Co Inc
B3: Financial Model
B4: =TODAY() -> 46301
B5: By: Shobitha SM

Sheet Summary Results Table
B2: ='Cover letter'!B2 -> Church & Dwight Co Inc
B3: SUMMARY RESULTS
B4: DCF VALUATION
B5: Scenarios | C5: Assumed Probablities | E5: Enterprise Values | F5: Equity Values | G5: Value Per Share | H5: Market Price
E6: ( $ millions) | F6: ( $ millions) | H6: 52 Week Range 81.33 - 106.34
B7: Base Case | C7: 0.5 | E7: 26835.762 | F7: 24453.762 | G7: 100.09727 | H7: Current Price | I7: 92.65
B8: Best Case | C8: 0.25 | E8: 32835.229 | F8: 30453.229 | G8: 124.65505 | H8: Recommendation: | I8: HOLD
B9: Worst Case | C9: 0.25 | E9: 26374.328 | F9: 23992.328 | G9: 98.208464
B10: Expected Value | E10: =IFERROR(E7*$C$7+E8*$C$8+E9*$C$9,"") -> 28220.27 | F10: =IFERROR(F7*$C$7+F8*$C$8+F9*$C$9,"") -> 25838.27 | G10: =IFERROR(G7*$C$7+G8*$C$8+G9*$C$9,"") -> 105.76451
B12: Multiple Based Valuation, Value per share
B13: Scenarios | C13: P/E Multiple | D13: EBITDA Multiple | E13: Revenue Multiple
B14: Base Case | C14: 59.002493 | D14: 69.697584 | E14: 71.447908
B15: Best Case | C15: 78.836812 | D15: 69.697584 | E15: 92.159825
B16: Worst Case | C16: 41.097849 | D16: 69.697584 | E16: 52.751047
B17: Expected Value | C17: =IFERROR(C14*$C$7+C15*$C$8+C16*$C$9,"") -> 59.484912 | D17: =IFERROR(D14*$C$7+D15*$C$8+D16*$C$9,"") -> 69.697584 | E17: =IFERROR(E14*$C$7+E15*$C$8+E16*$C$9,"") -> 71.951672
B19: Trading Multiples (Peer Average) | D19: Trading Multiple of CHD
B20: NTM TEV/Forward Total Revenue (Capital IQ) | C20: ='Assumption table'!K54 -> 13.83 | D20: ='Assumption table'!K58 -> 18.41
B21: NTM TEV/Forward EBITDA (Capital IQ) | C21: ='Assumption table'!K55 -> 3.1 | D21: ='Assumption table'!K59 -> 3.35
B22: NTM Forward P/E (Capital IQ) | C22: ='Assumption table'!K56 -> 17.2 | D22: ='Assumption table'!K60 -> 26.3

Sheet Assumption table
B2: ='Summary Results Table'!B2 -> Church & Dwight Co Inc
B3: MODEL ASSUMPTIONS
B6: GENERAL | I6: Capital Expenditure Assumptions, average of % Revenue | J6: 26E - 30E
B7: - | C7: First year of forecast period in the model: | F7: 2026 | I7: Land | J7: ='Data Source'!Q550 -> 0.0047739935
B8: - | C8: The model is a 5-year cash flow model discounted to Dec. 31, 2025 | I8: Buildings and improvements | J8: ='Data Source'!Q551 -> 0.056046274
I9: Machinery and equipment | J9: ='Data Source'!Q552 -> 0.15738719
I10: Software | J10: ='Data Source'!Q553 -> 0.021101728
I11: Office equipment and other assets | J11: ='Data Source'!Q554 -> 0.018930675
B12: Organic Growth | I12: Construction in progress | J12: ='Data Source'!Q555 -> 0.03217138
B13: Product volumes sold , based on historical arithmetic average | E13: 26E | F13: 27E - 30E
B14: Consumer Domestic: | E14: 0.0105 | F14: 0.01
B15: Consumer International: | E15: ='Data Source'!H198 -> 0.0352 | F15: ='Data Source'!I198 -> 0.0352 | I15: Depreciation Assumptions | J15: Straight Line
B16: SPD | E16: 0.005 | F16: 0.0005 | I16: Asset | J16: Useful Life
I17: Land | J17: No Depreciation
B18: Pricing/Product mix , based on historical arithmetic average | E18: 26E | F18: 27E - 30E | I18: Buildings and improvements | J18: 40
B19: Consumer Domestic: | E19: ='Data Source'!H184 -> 0.0312 | F19: ='Data Source'!I184 -> 0.0312 | I19: Machinery and equipment | J19: 15
B20: Consumer International: | E20: ='Data Source'!H199 -> 0.0264 | F20: ='Data Source'!I199 -> 0.0264 | I20: Software | J20: 10
B21: SPD | E21: ='Data Source'!H216 -> 0.0418 | F21: =E21 -> 0.0418 | I21: Office equipment and other assets | J21: 10
I22: Construction in progress | J22: N/A (not depreciated)
I23: Amortization Assumptions
B24: Inorganic Growth | I24: Asset | J24: Useful Life
B25: Acquisitions | E25: 26E | F25: 27E - 30E | I25: Trade names | J25: 20
B26: Consumer Domestic: | E26: ='Data Source'!H185 -> 0.025768577 | F26: ='Data Source'!I185 -> 0 | I26: Customer Relationships | J26: 15
B27: Consumer International: | E27: ='Data Source'!H202 -> 0.011212309 | F27: ='Data Source'!I202 -> 0 | I27: Patents/Formulas | J27: 10
B28: SPD | E28: 0 | F28: =E28 -> 0
B30: Exit of product lines | E30: 26E | F30: 27E - 30E
B31: Consumer Domestic: | E31: ='Data Source'!H186 -> -0.067 | F31: ='Data Source'!I186 -> 0 | I31: Long Term Debt Assumption | J31: 2026 | K31: 2027 | L31: 2028 | M31: 2029 | N31: 2030
B32: Consumer International: | E32: ='Data Source'!H201 -> -0.036 | F32: ='Data Source'!I201 -> 0 | I32: Beginning Debt Level as (2025), in $MM | J32: ='Data Source'!G598 -> 2205.1
B33: SPD | E33: ='Data Source'!H218 -> 0 | F33: =E33 -> 0 | I33: Long Term Debt Growth Rate | J33: 0
I34: Interest rate on long term debt | J34: ='Data Source'!M624 -> 0.041877805
I35: Long Term Debt Repayment
B36: Foreign exchange rate fluctuations / Other | E36: ='Data Source'!H221 -> 0 | F36: ='Data Source'!J221 -> 0 | I36: Long term debt+capital lease payment | J36: ='Data Source'!D642 -> 32.4 | K36: ='Data Source'!D643 -> 30.7 | L36: ='Data Source'!D644 -> 26.6 | M36: ='Data Source'!D645 -> 26 | N36: ='Data Source'!D646 -> 25.9
I37: Bond Principal Repayments | J37: 0 | K37: 425 | L37: 0 | M37: 0 | N37: 0
B38: Total Revenue Growth | E38: 26E | F38: 27E - 30E | I38: Total Scheduled Repayments | J38: =J36+J37 -> 32.4 | K38: =K36+K37 -> 455.7 | L38: =L36+L37 -> 26.6 | M38: =M36+M37 -> 26 | N38: =N36+N37 -> 25.9
B39: Consumer Domestic: | E39: =E14+E19+E26+E31+E36 -> 0.00046857669 | F39: =F14+F19+F26+F31+F36 -> 0.0412
B40: Consumer International: | E40: =E15+E20+E27+E32+E36 -> 0.036812309 | F40: =F15+F20+F27+F32+F36 -> 0.0616
B41: SPD | E41: =E16+E21+E28+E33+E36 -> 0.0468 | F41: =F16+F21+F28+F33+F36 -> 0.0423 | I41: Long Term Commitment Ex Operating Lease | J41: 2025 | K41: 2026
I42: Long term debt including capital lease payment schedule, in $MM | J42: $ 1,819 | K42: 566
I43: Of Which Capital Leasse, in $MM | J43: $ 104.0 | K43: 70.4
I44: Other Contractual Obligation ( Purchase), in $MM | J44: $ 2,925 | K44: 2462
...

Sheet Model
A2: Total Revenue Breakdown | B2: ='Data Source'!E227 -> 2023 | C2: ='Data Source'!F227 -> 2024 | D2: ='Data Source'!G227 -> 2025 | E2: =D2+1 -> 2026 | F2: =E2+1 -> 2027 | G2: =F2+1 -> 2028 | H2: =G2+1 -> 2029 | I2: =H2+1 -> 2030
A3: Consumer Domestic Segements
A4: Revenue | B4: ='Data Source'!E182 -> 4571.2 | C4: ='Data Source'!F182 -> 4732.3 | D4: ='Data Source'!G182 -> 4774.8 | E4: =D4*(1+E5) -> 4777.0374 | F4: =E4*(1+F5) -> 4973.8513 | G4: =F4*(1+G5) -> 5178.774 | H4: =G4*(1+H5) -> 5392.1395 | I4: =H4*(1+I5) -> 5614.2956
A5: YoY % | B5: ='Data Source'!E187 -> 0.107 | C5: ='Data Source'!F187 -> 0.035 | D5: ='Data Source'!G187 -> 0.009 | E5: ='Assumption table'!E39 -> 0.00046857669 | F5: ='Assumption table'!$F$39 -> 0.0412 | G5: ='Assumption table'!$F$39 -> 0.0412 | H5: ='Assumption table'!$F$39 -> 0.0412 | I5: ='Assumption table'!$F$39 -> 0.0412
A6: Change ('000) | B6: ='Data Source'!E188 -> 442.017 | C6: ='Data Source'!F188 -> 159.992 | D6: ='Data Source'!G188 -> 42.5907 | E6: =SUM(E7:E10) -> 2.23736 | F6: =SUM(F7:F10) -> 196.81394 | G6: =SUM(G7:G10) -> 204.92267 | H6: =SUM(H7:H10) -> 213.36549 | I6: =SUM(I7:I10) -> 222.15615
A7: Product volumes | B7: ='Data Source'!E189 -> 41.31 | C7: ='Data Source'!F189 -> 127.9936 | D7: ='Data Source'!G189 -> 0 | E7: =D$4*'Scenarios Table'!G12 -> 50.1354 | F7: =E$4*'Scenarios Table'!$H$12 -> 47.770374 | G7: =F$4*'Scenarios Table'!$H$12 -> 49.738513 | H7: =G$4*'Scenarios Table'!$H$12 -> 51.78774 | I7: =H$4*'Scenarios Table'!$H$12 -> 53.921395
A8: Pricing/Product mix | B8: ='Data Source'!E190 -> 194.157 | C8: ='Data Source'!F190 -> 31.9984 | D8: ='Data Source'!G190 -> -23.6615 | E8: =D$4*'Scenarios Table'!G19 -> 148.97376 | F8: =E$4*'Scenarios Table'!$H$19 -> 149.04357 | G8: =F$4*'Scenarios Table'!$H$19 -> 155.18416 | H8: =G$4*'Scenarios Table'!$H$19 -> 161.57775 | I8: =H$4*'Scenarios Table'!$H$19 -> 168.23475
A9: Acquisitions | B9: ='Data Source'!E191 -> 206.55 | C9: ='Data Source'!F191 -> 0 | D9: ='Data Source'!G191 -> 104.1106 | E9: =D$4*'Scenarios Table'!G26 -> 123.0398 | F9: =E$4*'Scenarios Table'!$H$26 -> 0 | G9: =F$4*'Scenarios Table'!$H$26 -> 0 | H9: =G$4*'Scenarios Table'!$H$26 -> 0 | I9: =H$4*'Scenarios Table'!$H$26 -> 0
A10: Exit of product lines | B10: ='Data Source'!E192 -> 0 | C10: ='Data Source'!F192 -> 0 | D10: ='Data Source'!G192 -> -37.8584 | E10: =D$4*'Scenarios Table'!G33 -> -319.9116 | F10: =E$4*'Scenarios Table'!$H$33 -> 0 | G10: =F$4*'Scenarios Table'!$H$33 -> 0 | H10: =G$4*'Scenarios Table'!$H$33 -> 0 | I10: =H$4*'Scenarios Table'!$H$33 -> 0
A11: Check | E11: =(E6/D4)-E5 -> -6.1257423e-18 | F11: =(F6/E4)-F5 -> 0 | G11: =(G6/F4)-G5 -> 0 | H11: =(H6/G4)-H5 -> 0 | I11: =(I6/H4)-I5 -> 0
A13: Consumer International Segements
A14: Revenue | B14: ='Data Source'!E197 -> 975.7 | C14: ='Data Source'!F197 -> 1071.5 | D14: ='Data Source'!G197 -> 1129.4 | E14: =D14*(1+E15) -> 1170.9758 | F14: =E14*(1+F15) -> 1243.1079 | G14: =F14*(1+G15) -> 1319.6834 | H14: =G14*(1+H15) -> 1400.9759 | I14: =H14*(1+I15) -> 1487.276
A15: YoY % | B15: ='Data Source'!E203 -> 0.089 | C15: ='Data Source'!F203 -> 0.098 | D15: ='Data Source'!G203 -> 0.054 | E15: ='Assumption table'!E40 -> 0.036812309 | F15: ='Assumption table'!$F$40 -> 0.0616 | G15: ='Assumption table'!$F$40 -> 0.0616 | H15: ='Assumption table'!$F$40 -> 0.0616 | I15: ='Assumption table'!$F$40 -> 0.0616
A16: Change ('000) | B16: ='Data Source'!E204 -> 79.7529 | C16: ='Data Source'!F204 -> 95.6186 | D16: ='Data Source'!G204 -> 57.861 | E16: =SUM(E17:E21) -> 41.575822 | F16: =SUM(F17:F21) -> 72.132111 | G16: =SUM(G17:G21) -> 76.575449 | H16: =SUM(H17:H21) -> 81.292496 | I16: =SUM(I17:I21) -> 86.300114
A17: Product volumes sold | B17: ='Data Source'!E205 -> 30.4674 | C17: ='Data Source'!F205 -> 55.6149 | D17: ='Data Source'!G205 -> 52.5035 | E17: =D$14*'Scenarios Table'!G42 -> 39.75488 | F17: =E$14*'Scenarios Table'!$H$42 -> 41.218349 | G17: =F$14*'Scenarios Table'!$H$42 -> 43.757399 | H17: =G$14*'Scenarios Table'!$H$42 -> 46.452855 | I17: =H$14*'Scenarios Table'!$H$42 -> 49.314351
A18: Pricing/Product mix | B18: ='Data Source'!E206 -> 45.7011 | C18: ='Data Source'!F206 -> 32.1981 | D18: ='Data Source'!G206 -> 6.429 | E18: =D$14*'Scenarios Table'!G49 -> 29.81616 | F18: =E$14*'Scenarios Table'!$H$49 -> 30.913762 | G18: =F$14*'Scenarios Table'!$H$49 -> 32.818049 | H18: =G$14*'Scenarios Table'!$H$49 -> 34.839641 | I18: =H$14*'Scenarios Table'!$H$49 -> 36.985763
A19: Foreign exchange rate fluctuations | B19: ='Data Source'!E207 -> 0.8961 | C19: ='Data Source'!F207 -> -1.9514 | D19: ='Data Source'!G207 -> -2.143 | E19: =D$14*'Assumption table'!E36 -> 0 | F19: =E$14*'Assumption table'!$F$36 -> 0 | G19: =F$14*'Assumption table'!$F$36 -> 0 | H19: =G$14*'Assumption table'!$F$36 -> 0 | I19: =H$14*'Assumption table'!$F$36 -> 0
A20: Acquisitions | B20: ='Data Source'!E209 -> 2.6883 | C20: ='Data Source'!F209 -> 9.757 | D20: ='Data Source'!G209 -> 10.715 | E20: =D$14*'Scenarios Table'!G56 -> 12.663182 | F20: =E$14*'Scenarios Table'!$H$56 -> 0 | G20: =F$14*'Scenarios Table'!$H$56 -> 0 | H20: =G$14*'Scenarios Table'!$H$56 -> 0 | I20: =H$14*'Scenarios Table'!$H$56 -> 0
A21: Exit of product lines | B21: ='Data Source'!E208 -> 0 | C21: ='Data Source'!F208 -> 0 | D21: ='Data Source'!G208 -> -9.6435 | E21: =D$14*'Scenarios Table'!G63 -> -40.6584 | F21: =E$14*'Scenarios Table'!$H$63 -> 0 | G21: =F$14*'Scenarios Table'!$H$63 -> 0 | H21: =G$14*'Scenarios Table'!$H$63 -> 0 | I21: =H$14*'Scenarios Table'!$H$63 -> 0
A22: Check | E22: =(E16/D14)-E15 -> 0 | F22: =(F16/E14)-F15 -> 0 | G22: =(G16/F14)-G15 -> 0 | H22: =(H16/G14)-H15 -> 0 | I22: =(I16/H14)-I15 -> 0
A24: SPD
A25: Revenue | B25: ='Data Source'!E214 -> 321 | C25: ='Data Source'!F214 -> 303.3 | D25: ='Data Source'!G214 -> 299 | E25: =D25*(1+E26) -> 312.9932 | F25: =E25*(1+F26) -> 326.23281 | G25: =F25*(1+G26) -> 340.03246 | H25: =G25*(1+H26) -> 354.41583 | I25: =H25*(1+I26) -> 369.40762
A26: YoY % | B26: ='Data Source'!E219 -> -0.079 | C26: ='Data Source'!F219 -> -0.055 | D26: ='Data Source'!G219 -> -0.014 | E26: ='Assumption table'!E41 -> 0.0468 | F26: ='Assumption table'!$F$41 -> 0.0423 | G26: ='Assumption table'!$F$41 -> 0.0423 | H26: ='Assumption table'!$F$41 -> 0.0423 | I26: ='Assumption table'!$F$41 -> 0.0423
A27: Change ('000) | B27: ='Data Source'!E220 -> -27.5315 | C27: ='Data Source'!F220 -> -17.655 | D27: ='Data Source'!G220 -> -4.2462 | E27: =SUM(E28:E31) -> 13.9932 | F27: =SUM(F28:F31) -> 13.239612 | G27: =SUM(G28:G31) -> 13.799648 | H27: =SUM(H28:H31) -> 14.383373 | I27: =SUM(I28:I31) -> 14.99179
A28: Product volumes | B28: ='Data Source'!E221 -> -25.092 | C28: ='Data Source'!F221 -> 12.84 | D28: ='Data Source'!G221 -> 0.9099 | E28: =D$25*'Scenarios Table'!G72 -> 1.495 | F28: =E$25*'Scenarios Table'!$H$72 -> 0.1564966 | G28: =F$25*'Scenarios Table'!$H$72 -> 0.16311641 | H28: =G$25*'Scenarios Table'!$H$72 -> 0.17001623 | I28: =H$25*'Scenarios Table'!$H$72 -> 0.17720792
A29: Pricing/Product mix | B29: ='Data Source'!E222 -> -2.4395 | C29: ='Data Source'!F222 -> 9.951 | D29: ='Data Source'!G222 -> 6.9759 | E29: =D$25*'Scenarios Table'!G79 -> 12.4982 | F29: =E$25*'Scenarios Table'!$H$79 -> 13.083116 | G29: =F$25*'Scenarios Table'!$H$79 -> 13.636532 | H29: =G$25*'Scenarios Table'!$H$79 -> 14.213357 | I29: =H$25*'Scenarios Table'!$H$79 -> 14.814582
A30: Acquisitions | B30: ='Data Source'!E223 -> 0 | C30: ='Data Source'!F223 -> 0 | D30: ='Data Source'!G223 -> 0.9099 | E30: =D$25*'Assumption table'!E28 -> 0 | F30: =E$25*'Assumption table'!$F$28 -> 0 | G30: =F$25*'Assumption table'!$F$28 -> 0 | H30: =G$25*'Assumption table'!$F$28 -> 0 | I30: =H$25*'Assumption table'!$F$28 -> 0
A31: Exit of product lines | B31: ='Data Source'!E224 -> 0 | C31: ='Data Source'!F224 -> -40.446 | D31: ='Data Source'!G224 -> -13.0419 | E31: =D$25*'Assumption table'!E33 -> 0 | F31: =E$25*'Assumption table'!$F$33 -> 0 | G31: =F$25*'Assumption table'!$F$33 -> 0 | H31: =G$25*'Assumption table'!$F$33 -> 0 | I31: =H$25*'Assumption table'!$F$33 -> 0
A32: Check | E32: =(E27/D25)-E26 -> 0 | F32: =(F27/E25)-F26 -> 0 | G32: =(G27/F25)-G26 -> 0 | H32: =(H27/G25)-H26 -> 0 | I32: =(I27/H25)-I26 -> 0
A34: Total Consolidated Revenue
A35: Household Products | B35: ='Data Source'!E229 -> 2484.1 | C35: ='Data Source'!F229 -> 2584.3 | D35: ='Data Source'!G229 -> 2556.9 | E35: ='Assumption table'!$F$46*E37 -> 2587.7288 | F35: ='Assumption table'!$F$46*F37 -> 2694.3432 | G35: ='Assumption table'!$F$46*G37 -> 2805.3501 | H35: ='Assumption table'!$F$46*H37 -> 2920.9305 | I35: ='Assumption table'!$F$46*I37 -> 3041.2729
A36: Personal Care Products | B36: ='Data Source'!E231 -> 2087.1 | C36: ='Data Source'!F231 -> 2148 | D36: ='Data Source'!G231 -> 2217.9 | E36: ='Assumption table'!$F$47*E37 -> 2189.3086 | F36: ='Assumption table'!$F$47*F37 -> 2279.5081 | G36: ='Assumption table'!$F$47*G37 -> 2373.4238 | H36: ='Assumption table'!$F$47*H37 -> 2471.2089 | I36: ='Assumption table'!$F$47*I37 -> 2573.0227
A37: Total Consumer Domestic | B37: ='Data Source'!E228 -> 4571.2 | C37: ='Data Source'!F228 -> 4732.3 | D37: ='Data Source'!G228 -> 4774.8 | E37: =E4 -> 4777.0374 | F37: =F4 -> 4973.8513 | G37: =G4 -> 5178.774 | H37: =H4 -> 5392.1395 | I37: =I4 -> 5614.2956
A39: Total Consumer International | B39: ='Data Source'!E233 -> 975.7 | C39: ='Data Source'!F233 -> 1071.5 | D39: ='Data Source'!G233 -> 1129.4 | E39: =E14 -> 1170.9758 | F39: =F14 -> 1243.1079 | G39: =G14 -> 1319.6834 | H39: =H14 -> 1400.9759 | I39: =I14 -> 1487.276
A41: Total SPD | B41: ='Data Source'!E234 -> 321 | C41: ='Data Source'!F234 -> 303.3 | D41: ='Data Source'!G234 -> 299 | E41: =E25 -> 312.9932 | F41: =F25 -> 326.23281 | G41: =G25 -> 340.03246 | H41: =H25 -> 354.41583 | I41: =I25 -> 369.40762
A42: Total Consolidated Net Sales | B42: ='Data Source'!E235 -> 5867.9 | C42: ='Data Source'!F235 -> 6107.1 | D42: ='Data Source'!G235 -> 6203.2 | E42: =SUM(E37:E41) -> 6261.0064 | F42: =SUM(F37:F41) -> 6543.192 | G42: =SUM(G37:G41) -> 6838.4898 | H42: =SUM(H37:H41) -> 7147.5312 | I42: =SUM(I37:I41) -> 7470.9792
A43: Check | B43: =B37+B39+B41-B42 -> 0 | C43: =C37+C39+C41-C42 -> 0 | D43: =D37+D39+D41-D42 -> 0 | E43: =E37+E39+E41-E42 -> 0 | F43: =F37+F39+F41-F42 -> 0 | G43: =G37+G39+G41-G42 -> 0 | H43: =H37+H39+H41-H42 -> 0 | I43: =I37+I39+I41-I42 -> 0
A44: YoY% | B44: ='Data Source'!E236 -> 0.092 | C44: ='Data Source'!F236 -> 0.041 | D44: ='Data Source'!G236 -> 0.016 | E44: =E42/D42-1 -> 0.0093188003 | F44: =F42/E42-1 -> 0.045070336 | G44: =G42/F42-1 -> 0.045130537 | H44: =H42/G42-1 -> 0.045191463 | I44: =I42/H42-1 -> 0.045253115
A48: Segemental Detail Breakdown | B48: =B$2 -> 2023 | C48: =C$2 -> 2024 | D48: =D$2 -> 2025 | E48: =E$2 -> 2026 | F48: =F$2 -> 2027 | G48: =G$2 -> 2028 | H48: =H$2 -> 2029 | I48: =I$2 -> 2030
A49: Consumer Domestic Segements
...

Sheet Scenarios Table
B1: Church & Dwight Co Inc
B2: Volumes, Pricing/Product mix, Acquisitions, Exit of product lines, COGS, Operating Expenses, Terminal Value and Discount Rate Scenarios
A3: SWITCH | B3: 1
G8: 2026 | H8: 2027 | I8: 2028 | J8: 2029 | K8: 2030
B9: Consumer Domestic:
B10: Volume Scenario
C11: Product volumes
D12: Currently Running | G12: =CHOOSE($B$3,G14,G15,G16) -> 0.0105 | H12: =CHOOSE($B$3,H14,H15,H16) -> 0.01 | I12: =CHOOSE($B$3,I14,I15,I16) -> 0.01 | J12: =CHOOSE($B$3,J14,J15,J16) -> 0.01 | K12: =CHOOSE($B$3,K14,K15,K16) -> 0.01
D14: Base Case | G14: ='Assumption table'!E14 -> 0.0105 | H14: ='Assumption table'!F14 -> 0.01 | I14: ='Assumption table'!F14 -> 0.01 | J14: ='Assumption table'!F14 -> 0.01 | K14: ='Assumption table'!F14 -> 0.01
D15: Best Case | G15: =G14+'Assumption table'!$F107 -> 0.0305 | H15: =H14+'Assumption table'!$F107 -> 0.03 | I15: =I14+'Assumption table'!$F107 -> 0.03 | J15: =J14+'Assumption table'!$F107 -> 0.03 | K15: =K14+'Assumption table'!$F107 -> 0.03
D16: Worst Case | G16: =G14+'Assumption table'!$F108 -> -0.0095 | H16: =H14+'Assumption table'!$F108 -> -0.01 | I16: =I14+'Assumption table'!$F108 -> -0.01 | J16: =J14+'Assumption table'!$F108 -> -0.01 | K16: =K14+'Assumption table'!$F108 -> -0.01
C18: Pricing/Product mix
D19: Currently Running | G19: =CHOOSE($B$3,G21,G22,G23) -> 0.0312 | H19: =CHOOSE($B$3,H21,H22,H23) -> 0.0312 | I19: =CHOOSE($B$3,I21,I22,I23) -> 0.0312 | J19: =CHOOSE($B$3,J21,J22,J23) -> 0.0312 | K19: =CHOOSE($B$3,K21,K22,K23) -> 0.0312
D21: Base Case | G21: ='Assumption table'!E19 -> 0.0312 | H21: ='Assumption table'!F19 -> 0.0312 | I21: ='Assumption table'!F19 -> 0.0312 | J21: ='Assumption table'!F19 -> 0.0312 | K21: ='Assumption table'!F19 -> 0.0312
D22: Best Case | G22: =G21+'Assumption table'!$F110 -> 0.0412 | H22: =H21+'Assumption table'!$F110 -> 0.0412 | I22: =I21+'Assumption table'!$F110 -> 0.0412 | J22: =J21+'Assumption table'!$F110 -> 0.0412 | K22: =K21+'Assumption table'!$F110 -> 0.0412
D23: Worst Case | G23: =G21+'Assumption table'!$F111 -> 0.0262 | H23: =H21+'Assumption table'!$F111 -> 0.0262 | I23: =I21+'Assumption table'!$F111 -> 0.0262 | J23: =J21+'Assumption table'!$F111 -> 0.0262 | K23: =K21+'Assumption table'!$F111 -> 0.0262
C25: Acquisitions
D26: Currently Running | G26: =CHOOSE($B$3,G28,G29,G30) -> 0.025768577 | H26: =CHOOSE($B$3,H28,H29,H30) -> 0 | I26: =CHOOSE($B$3,I28,I29,I30) -> 0 | J26: =CHOOSE($B$3,J28,J29,J30) -> 0 | K26: =CHOOSE($B$3,K28,K29,K30) -> 0
D28: Base Case | G28: ='Assumption table'!E26 -> 0.025768577 | H28: ='Assumption table'!F26 -> 0 | I28: ='Assumption table'!F26 -> 0 | J28: ='Assumption table'!F26 -> 0 | K28: ='Assumption table'!F26 -> 0
D29: Best Case | G29: =G28+'Assumption table'!$F113 -> 0.045768577 | H29: =H28+'Assumption table'!$F113 -> 0.02 | I29: =I28+'Assumption table'!$F113 -> 0.02 | J29: =J28+'Assumption table'!$F113 -> 0.02 | K29: =K28+'Assumption table'!$F113 -> 0.02
D30: Worst Case | G30: =G28+'Assumption table'!$F114 -> 0.025768577 | H30: =H28+'Assumption table'!$F114 -> 0 | I30: =I28+'Assumption table'!$F114 -> 0 | J30: =J28+'Assumption table'!$F114 -> 0 | K30: =K28+'Assumption table'!$F114 -> 0
C32: Exit of product lines
D33: Currently Running | G33: =CHOOSE($B$3,G35,G36,G37) -> -0.067 | H33: =CHOOSE($B$3,H35,H36,H37) -> 0 | I33: =CHOOSE($B$3,I35,I36,I37) -> 0 | J33: =CHOOSE($B$3,J35,J36,J37) -> 0 | K33: =CHOOSE($B$3,K35,K36,K37) -> 0
D35: Base Case | G35: ='Assumption table'!E31 -> -0.067 | H35: ='Assumption table'!F31 -> 0 | I35: ='Assumption table'!F31 -> 0 | J35: ='Assumption table'!F31 -> 0 | K35: ='Assumption table'!F31 -> 0
D36: Best Case | G36: =G35+'Assumption table'!$F116 -> -0.067 | H36: =H35+'Assumption table'!$F116 -> 0 | I36: =I35+'Assumption table'!$F116 -> 0 | J36: =J35+'Assumption table'!$F116 -> 0 | K36: =K35+'Assumption table'!$F116 -> 0
D37: Worst Case | G37: =G35+'Assumption table'!$F117 -> -0.067 | H37: =H35+'Assumption table'!$F117 -> 0 | I37: =I35+'Assumption table'!$F117 -> 0 | J37: =J35+'Assumption table'!$F117 -> 0 | K37: =K35+'Assumption table'!$F117 -> 0
B39: Consumer International:
B40: Volume Scenario
C41: Product volumes
D42: Currently Running | G42: =CHOOSE($B$3,G44,G45,G46) -> 0.0352 | H42: =CHOOSE($B$3,H44,H45,H46) -> 0.0352 | I42: =CHOOSE($B$3,I44,I45,I46) -> 0.0352 | J42: =CHOOSE($B$3,J44,J45,J46) -> 0.0352 | K42: =CHOOSE($B$3,K44,K45,K46) -> 0.0352
D44: Base Case | G44: ='Assumption table'!E15 -> 0.0352 | H44: ='Assumption table'!F15 -> 0.0352 | I44: ='Assumption table'!F15 -> 0.0352 | J44: ='Assumption table'!F15 -> 0.0352 | K44: ='Assumption table'!F15 -> 0.0352
D45: Best Case | G45: =G44+'Assumption table'!$F120 -> 0.0652 | H45: =H44+'Assumption table'!$F120 -> 0.0652 | I45: =I44+'Assumption table'!$F120 -> 0.0652 | J45: =J44+'Assumption table'!$F120 -> 0.0652 | K45: =K44+'Assumption table'!$F120 -> 0.0652
D46: Worst Case | G46: =G44+'Assumption table'!$F121 -> 0.0252 | H46: =H44+'Assumption table'!$F121 -> 0.0252 | I46: =I44+'Assumption table'!$F121 -> 0.0252 | J46: =J44+'Assumption table'!$F121 -> 0.0252 | K46: =K44+'Assumption table'!$F121 -> 0.0252
C48: Pricing/Product mix
D49: Currently Running | G49: =CHOOSE($B$3,G51,G52,G53) -> 0.0264 | H49: =CHOOSE($B$3,H51,H52,H53) -> 0.0264 | I49: =CHOOSE($B$3,I51,I52,I53) -> 0.0264 | J49: =CHOOSE($B$3,J51,J52,J53) -> 0.0264 | K49: =CHOOSE($B$3,K51,K52,K53) -> 0.0264
D51: Base Case | G51: ='Assumption table'!E20 -> 0.0264 | H51: ='Assumption table'!F20 -> 0.0264 | I51: ='Assumption table'!F20 -> 0.0264 | J51: ='Assumption table'!F20 -> 0.0264 | K51: ='Assumption table'!F20 -> 0.0264
D52: Best Case | G52: =G51+'Assumption table'!$F123 -> 0.0314 | H52: =H51+'Assumption table'!$F123 -> 0.0314 | I52: =I51+'Assumption table'!$F123 -> 0.0314 | J52: =J51+'Assumption table'!$F123 -> 0.0314 | K52: =K51+'Assumption table'!$F123 -> 0.0314
D53: Worst Case | G53: =G51+'Assumption table'!$F124 -> 0.0254 | H53: =H51+'Assumption table'!$F124 -> 0.0254 | I53: =I51+'Assumption table'!$F124 -> 0.0254 | J53: =J51+'Assumption table'!$F124 -> 0.0254 | K53: =K51+'Assumption table'!$F124 -> 0.0254
C55: Acquisitions
D56: Currently Running | G56: =CHOOSE($B$3,G58,G59,G60) -> 0.011212309 | H56: =CHOOSE($B$3,H58,H59,H60) -> 0 | I56: =CHOOSE($B$3,I58,I59,I60) -> 0 | J56: =CHOOSE($B$3,J58,J59,J60) -> 0 | K56: =CHOOSE($B$3,K58,K59,K60) -> 0
...

Sheet WACC Model
A1: Principal Due in Millions of the reported currency.
A2: Debt Structure
A3: Debt description | B3: Type | C3: Principal Due (USD) | D3: Coupon/Base Rate | E3: Debt Weights | F3: Debt Rd Contribution
A4: 2.30% Senior Notes Due December 15, 2031 | B4: Bonds and Notes | C4: ='Data Source'!C616 -> 400 | D4: ='Data Source'!D616 -> 0.023 | E4: =C4/$C$10 -> 0.16653483 | F4: =D4*E4 -> 0.003830301
A5: 3.15% Senior Notes Due August 1, 2027 | B5: Bonds and Notes | C5: ='Data Source'!C617 -> 425 | D5: ='Data Source'!D617 -> 0.0315 | E5: =C5/$C$10 -> 0.17694325 | F5: =D5*E5 -> 0.0055737125
A6: 3.95% Senior Notes Due August 1, 2047 | B6: Bonds and Notes | C6: ='Data Source'!C618 -> 400 | D6: ='Data Source'!D618 -> 0.0395 | E6: =C6/$C$10 -> 0.16653483 | F6: =D6*E6 -> 0.0065781257
A7: 5.00% Senior Notes Due June 15, 2052 | B7: Bonds and Notes | C7: ='Data Source'!C619 -> 500 | D7: ='Data Source'!D619 -> 0.05 | E7: =C7/$C$10 -> 0.20816853 | F7: =D7*E7 -> 0.010408427
A8: 5.60% Senior Notes Due November 15, 2032 | B8: Bonds and Notes | C8: ='Data Source'!C620 -> 500 | D8: ='Data Source'!D620 -> 0.056 | E8: =C8/$C$10 -> 0.20816853 | F8: =D8*E8 -> 0.011657438
A9: Operating Lease Obligation | B9: Capital Lease | C9: ='Data Source'!C622 -> 176.9 | D9: ='Data Source'!D622 -> 0.052 | E9: =C9/$C$10 -> 0.073650027 | F9: =D9*E9 -> 0.0038298014
A10: Total Interest bearing debt including capital Lease | C10: =SUM(C4:C9) -> 2401.9 | F10: =SUM(F4:F9) -> 0.041877805 | G10: Weighted Cost of debt
A13: Cost of Equity (CAPM)
A14: Equity Beta | B14: =SLOPE('Data Source'!D656:D726,'Data Source'!E656:E726) -> 0.53009556
A15: Market Risk Premium | B15: 0.055
A16: Risk Free Rate (20 Years Treasury) | B16: 0.0482 | C16: Source: https://www.treasury.gov | E16: as of May 2, 2025
A17: Equity Cost of Capital of CHD | B17: =B16+B14*B15 -> 0.077355256 | C17: CAPM
A20: Weighted Average Cost of Capital Calculations
A21: Tax Rate | B21: 0.23
A22: Market Value of Equity | B22: ='Data Source'!B726*'Data Source'!G421 -> 20421.037 | C22: Market Capitalization table
A23: Market Value of Debt long term debt including Capital Lease | B23: =C10 -> 2401.9 | C23: See above
A24: E/V | B24: =B22/(B22+B23) -> 0.89475938
A25: D/V | B25: =B23/(B22+B23) -> 0.10524062
A26: WACC | B26: =B24*B17+B25*F10*(1-B21) -> 0.07260792

Sheet DCF
F3: ="Currently Running: "&CHOOSE('Scenarios Table'!B3,"BASE CASE","BEST CASE","WORST CASE") -> Currently Running: BASE CASE
A4: Cost of Equity | B4: ='Scenarios Table'!G150 -> 0.077355256
A5: Cost of Debt | B5: ='Scenarios Table'!G157 -> 0.041877805
A6: WACC | B6: ='WACC Model'!B24*B4+'WACC Model'!B25*B5*(1-'WACC Model'!B21) -> 0.07260792
A7: Terminal, Sustainable Long Term Growth Rate | B7: ='Scenarios Table'!G142 -> 0.03 | D7: 2026 | E7: 2027 | F7: 2028 | G7: 2029 | H7: 2030
C9: In millions of $
C11: FCF to Equity
C12: Net Income | D12: =Model!E266 -> 838.04123 | E12: =Model!F266 -> 884.07466 | F12: =Model!G266 -> 932.16715 | G12: =Model!H266 -> 982.41355 | H12: =Model!I266 -> 1034.9132
C13: Depreciation | D13: =Model!E276+Model!E277 -> 265.66045 | E13: =Model!F276+Model!F277 -> 270.14632 | F13: =Model!G276+Model!G277 -> 274.84063 | G13: =Model!H276+Model!H277 -> 279.75342 | H13: =Model!I276+Model!I277 -> 284.89524
C14: CAPEX | D14: =Model!E301 -> -121.26666 | E14: =Model!F301 -> -81.94989 | F14: =Model!G301 -> -85.757793 | G14: =Model!H301 -> -89.749085 | H14: =Model!I301 -> -93.932951
C15: Changes in working capital | D15: =Model!E298 -> -182.95034 | E15: =Model!F298 -> 5.5594104 | F15: =Model!G298 -> 5.8177353 | G15: =Model!H298 -> 6.0885012 | H15: =Model!I298 -> 6.3723311
C16: Net Debt | D16: =Model!E309+Model!E310+Model!E311 -> 0 | E16: =Model!F309+Model!F310+Model!F311 -> 0 | F16: =Model!G309+Model!G310+Model!G311 -> 0 | G16: =Model!H309+Model!H310+Model!H311 -> 0 | H16: =Model!I309+Model!I310+Model!I311 -> 0
C17: FCF to Equity (NI+Dep-Capex-chge NWC+ Net Debt) | D17: =D12+D13+D14+D15+D16 -> 799.48467 | E17: =E12+E13+E14+E15+E16 -> 1077.8305 | F17: =F12+F13+F14+F15+F16 -> 1127.0677 | G17: =G12+G13+G14+G15+G16 -> 1178.5064 | H17: =H12+H13+H14+H15+H16 -> 1232.2479
C18: Terminal Value at end of 2030 | H18: =H17*(1+$B$7)/($B$4-$B$7) -> 26801.994
C19: Total FCF to Equity (both first stage and second stage) | D19: =D17 -> 799.48467 | E19: =E17 -> 1077.8305 | F19: =F17 -> 1127.0677 | G19: =G17 -> 1178.5064 | H19: =H17+H18 -> 28034.242
C20: Total Equity Value | D20: =NPV($B$4,D19:H19) -> 22761.746
C21: Total number of Shares Outstanding, in Millions | D21: ='Data Source'!G421 -> 244.3
C22: Per Share | D22: =D20/D21 -> 93.171291
C23: Total FCF to the Firm
C24: After Tax Interest Expense | D24: =-Model!E262*(1-'WACC Model'!$B$21) -> 71.105456 | E24: =-Model!F262*(1-'WACC Model'!$B$21) -> 71.105456 | F24: =-Model!G262*(1-'WACC Model'!$B$21) -> 71.105456 | G24: =-Model!H262*(1-'WACC Model'!$B$21) -> 71.105456 | H24: =-Model!I262*(1-'WACC Model'!$B$21) -> 71.105456
C26: Total FCF to the Firm (Total FCF Equity + After tax Interest Expense - Net Debt) | D26: =D17+D24-D16 -> 870.59012 | E26: =E17+E24-E16 -> 1148.936 | F26: =F17+F24-F16 -> 1198.1732 | G26: =G17+G24-G16 -> 1249.6118 | H26: =H17+H24-H16 -> 1303.3533
C27: Terminal Value at end of 2030 | H27: =H26*(1+$B$7)/($B$6-$B$7) -> 31507.145
C28: Total FCF to the Firm | D28: =D26 -> 870.59012 | E28: =E26 -> 1148.936 | F28: =F26 -> 1198.1732 | G28: =G26 -> 1249.6118 | H28: =H26+H27 -> 32810.498
C29: Enterprise Value | D29: =NPV($B$6,D28:H28) -> 26835.762
C30: Less Total Debt | D30: ='Data Source'!G745 -> 2382
C31: Total Equity Value | D31: =D29-D30 -> 24453.762
C32: Number of Shares (in millions) | D32: =D21 -> 244.3
C33: Equity Value Per Share | D33: =D31/D32 -> 100.09727
F37: Growth Rate
E38: =D33 -> 100.09727 | F38: 0.01 | G38: 0.02 | H38: 0.03 | I38: 0.04 | J38: 0.05
D39: WACC | E39: 0.07 | F39: 73.428503 | G39: 86.995456 | H39: 107.34589 | I39: 141.26327 | J39: 209.09803
E40: 0.072 | F40: 70.678821 | G40: 83.209209 | H40: 101.70645 | I40: 131.76446 | J40: 189.14794
E41: 0.075 | F41: 66.872272 | G41: 78.046789 | H41: 94.187759 | I41: 119.55214 | J41: 165.20803
E42: 0.079 | F42: 62.312985 | G42: 71.981323 | H42: 85.595921 | I42: 106.19236 | J42: 140.99325
E43: 0.08 | F43: 61.254791 | G43: 70.591512 | H43: 83.662921 | I43: 103.27004 | J43: 135.94856
E44: 0.084 | F44: 57.308805 | G44: 65.467296 | H44: 76.647451 | I44: 92.909495 | J44: 118.73745

Sheet Multiples Valuation
E1: Currently Running: BASE CASE
A4: Trading Multiples ( The average of the top Comparables) | D4: Trading Multiple of CHD
A5: NTM EV/EBITDA (Peer Median) | B5: ='Assumption table'!K54 -> 13.83 | D5: CHD EV/EBITDA (TTM) | E5: ='Assumption table'!K58 -> 18.41
A6: NTM EV/Revenue (Peer Median) | B6: ='Assumption table'!K55 -> 3.1 | D6: CHD EV/Revenue | E6: ='Assumption table'!K59 -> 3.35
A7: NTM Fwd P/E (Peer Median) | B7: ='Assumption table'!K56 -> 17.2 | D7: CHD Fwd P/E | E7: ='Assumption table'!K60 -> 26.3
A10: CHD NTM data | D10: Valuation using CHD's Own Multiples
A11: CHD In MM $, except EPS
A12: Forward Total Revenue (2026) | B12: =Model!E250 -> 6261.0064 | D12: Forward Total Revenue (2026) | E12: =B12 -> 6261.0064
A13: Forward EBITDA (2026) | B13: =Model!E259+Model!E256+Model!E257 -> 1434.3257 | D13: Forward EBITDA (2026) | E13: =B13 -> 1434.3257
A14: Forward Net Income, 2026 | B14: =Model!E266 -> 838.04123 | D14: Forward Net Income, 2026 | E14: =B14 -> 838.04123
A15: Number of Shares outstanding (MM) | B15: =DCF!D32 -> 244.3 | D15: Number of Shares outstanding (MM) | E15: =B15 -> 244.3
A16: Forward EPS | B16: =B14/B15 -> 3.4303775 | D16: Forward EPS | E16: =B16 -> 3.4303775
A20: Total Enterprise Value, based on EBITDA Multiple | B20: =B13*B5 -> 19836.724 | D20: Total Enterprise Value, based on EBITDA Multiple | E20: =E13*'Assumption table'!K54 -> 19836.724
A21: Total Debt | B21: =DCF!D30 -> 2382 | D21: Total Debt | E21: =B21 -> 2382
A22: Total Equity | B22: =B20-B21 -> 17454.724 | D22: Total Equity | E22: =E20-E21 -> 17454.724
A23: Equity per share | B23: =B22/B15 -> 71.447908 | D23: Equity per share | E23: =E22/E15 -> 71.447908
A25: Total Enterprise Value, based on Revenue Multiple | B25: =B12*B6 -> 19409.12 | D25: Total Enterprise Value, based on Revenue Multiple | E25: =E12*'Assumption table'!K55 -> 19409.12
A26: Total Debt | B26: =DCF!D30 -> 2382 | D26: Total Debt | E26: =B26 -> 2382
A27: Total Equity | B27: =B25-B26 -> 17027.12 | D27: Total Equity | E27: =E25-E26 -> 17027.12
A28: Equity per share | B28: =B27/B15 -> 69.697584 | D28: Equity per share | E28: =E27/E15 -> 69.697584
A30: Equity Value, based on PE Multiple | B30: =B16*B7 -> 59.002493 | D30: Equity Value, based on PE Multiple | E30: =E16*E7 -> 90.218929
A33: Relative Valuation — CHD vs. Peer Group
A34: As of May 2, 2026
A36: Company | B36: EV/EBITDA | C36: P/E (TTM) | D36: Fwd P/E | E36: EV/Revenue | F36: EV/FCF | G36: PEG
A37: CHD (Church & Dwight) | B37: =VALUE(SUBSTITUTE('Data Source'!B773,"x","")) -> 18.41 | C37: =VALUE(SUBSTITUTE('Data Source'!C773,"x","")) -> 32.83 | D37: =VALUE(SUBSTITUTE('Data Source'!D773,"x","")) -> 26.3 | E37: =VALUE(SUBSTITUTE('Data Source'!E773,"x","")) -> 3.35 | F37: =VALUE(SUBSTITUTE('Data Source'!F773,"x","")) -> 23.28 | G37: =VALUE(SUBSTITUTE('Data Source'!G773,"x","")) -> 3.66
A38: Procter & Gamble | B38: =VALUE(SUBSTITUTE('Data Source'!B774,"x","")) -> 14.94 | C38: =VALUE(SUBSTITUTE('Data Source'!C774,"x","")) -> 21.61 | D38: =VALUE(SUBSTITUTE('Data Source'!D774,"x","")) -> 19.5 | E38: =VALUE(SUBSTITUTE('Data Source'!E774,"x","")) -> 3.8 | F38: =VALUE(SUBSTITUTE('Data Source'!F774,"x","")) -> 22 | G38: =VALUE(SUBSTITUTE('Data Source'!G774,"x","")) -> 2.8
A39: Colgate-Palmolive | B39: =VALUE(SUBSTITUTE('Data Source'!B775,"x","")) -> 15.24 | C39: =VALUE(SUBSTITUTE('Data Source'!C775,"x","")) -> 31.76 | D39: =VALUE(SUBSTITUTE('Data Source'!D775,"x","")) -> 21.77 | E39: =VALUE(SUBSTITUTE('Data Source'!E775,"x","")) -> 3.6 | F39: =VALUE(SUBSTITUTE('Data Source'!F775,"x","")) -> 20.41 | G39: =VALUE(SUBSTITUTE('Data Source'!G775,"x","")) -> 4.29
A40: Kimberly-Clark | B40: =VALUE(SUBSTITUTE('Data Source'!B776,"x","")) -> 12.53 | C40: =VALUE(SUBSTITUTE('Data Source'!C776,"x","")) -> 20.63 | D40: =VALUE(SUBSTITUTE('Data Source'!D776,"x","")) -> 13.22 | E40: =VALUE(SUBSTITUTE('Data Source'!E776,"x","")) -> 2.2 | F40: =VALUE(SUBSTITUTE('Data Source'!F776,"x","")) -> 24.45 | G40: =VALUE(SUBSTITUTE('Data Source'!G776,"x","")) -> 3.46
A41: Clorox | B41: =VALUE(SUBSTITUTE('Data Source'!B777,"x","")) -> 10.75 | C41: =VALUE(SUBSTITUTE('Data Source'!C777,"x","")) -> 14.42 | D41: =VALUE(SUBSTITUTE('Data Source'!D777,"x","")) -> 13.9 | E41: =VALUE(SUBSTITUTE('Data Source'!E777,"x","")) -> 2.16 | F41: =VALUE(SUBSTITUTE('Data Source'!F777,"x","")) -> 36.47 | G41: =VALUE(SUBSTITUTE('Data Source'!G777,"x","")) -> 2.1
A42: Reckitt Benckiser | B42: =VALUE(SUBSTITUTE('Data Source'!B778,"x","")) -> 13.79 | C42: =VALUE(SUBSTITUTE('Data Source'!C778,"x","")) -> 33.14 | D42: =VALUE(SUBSTITUTE('Data Source'!D778,"x","")) -> 17.47 | E42: =VALUE(SUBSTITUTE('Data Source'!E778,"x","")) -> 3.1 | F42: =VALUE(SUBSTITUTE('Data Source'!F778,"x","")) -> 23.45 | G42: =VALUE(SUBSTITUTE('Data Source'!G778,"x","")) -> 2.9
A43: Haleon | B43: =VALUE(SUBSTITUTE('Data Source'!B779,"x","")) -> 13.83 | C43: =VALUE(SUBSTITUTE('Data Source'!C779,"x","")) -> 18.31 | D43: =VALUE(SUBSTITUTE('Data Source'!D779,"x","")) -> 16.55 | E43: =VALUE(SUBSTITUTE('Data Source'!E779,"x","")) -> 3.4 | F43: =VALUE(SUBSTITUTE('Data Source'!F779,"x","")) -> 16.19 | G43: =VALUE(SUBSTITUTE('Data Source'!G779,"x","")) -> 2.5
A44: Unilever | B44: =VALUE(SUBSTITUTE('Data Source'!B780,"x","")) -> 14.64 | C44: =VALUE(SUBSTITUTE('Data Source'!C780,"x","")) -> 19.8 | D44: =VALUE(SUBSTITUTE('Data Source'!D780,"x","")) -> 17.2 | E44: =VALUE(SUBSTITUTE('Data Source'!E780,"x","")) -> 2.5 | F44: =VALUE(SUBSTITUTE('Data Source'!F780,"x","")) -> 21 | G44: =VALUE(SUBSTITUTE('Data Source'!G780,"x","")) -> 2.6
A46: Peer Median | B46: =MEDIAN(B38:B44) -> 13.83 | C46: =MEDIAN(C38:C44) -> 20.63 | D46: =MEDIAN(D38:D44) -> 17.2 | E46: =MEDIAN(E38:E44) -> 3.1 | F46: =MEDIAN(F38:F44) -> 22 | G46: =MEDIAN(G38:G44) -> 2.8
A47: Peer Mean | B47: =AVERAGE(B38:B44) -> 13.674286 | C47: =AVERAGE(C38:C44) -> 22.81 | D47: =AVERAGE(D38:D44) -> 17.087143 | E47: =AVERAGE(E38:E44) -> 2.9657143 | F47: =AVERAGE(F38:F44) -> 23.424286 | G47: =AVERAGE(G38:G44) -> 2.95
A49: CHD Premium/(Discount) to Peer Median | B49: =B37/B46-1 -> 0.33116414 | C49: =C37/C46-1 -> 0.59137179 | D49: =D37/D46-1 -> 0.52906977 | E49: =E37/E46-1 -> 0.080645161 | F49: =F37/F46-1 -> 0.058181818 | G49: =G37/G46-1 -> 0.30714286

Sheet Data Source
A1: Global Factors/Trends
A2: Global Inflation Trends (2020–2031)
A3: Source: IMF World Economic Outlook, April 2025
A5: Year | B5: World | C5: Advanced | D5: Emerging | E5: US | F5: Euro Area | G5: Data Type
A6: 2020 | B6: 0.032 | C6: 0.007 | D6: 0.051 | E6: 0.02027 | F6: 0.003 | G6: Actual
A7: 2021 | B7: 0.047 | C7: 0.031 | D7: 0.059 | E7: 0.047 | F7: 0.026 | G7: Actual
A8: 2022 | B8: 0.087 | C8: 0.073 | D8: 0.098 | E8: 0.08 | F8: 0.084 | G8: Actual
A9: 2023 | B9: 0.069 | C9: 0.046 | D9: 0.085 | E9: 0.041 | F9: 0.054 | G9: Actual
A10: 2024 | B10: 0.058 | C10: 0.027 | D10: 0.078 | E10: 0.029 | F10: 0.024 | G10: Actual
A11: 2025 | B11: 0.041 | C11: 0.025 | D11: 0.057 | E11: 0.027 | F11: 0.021 | G11: Actual
A12: 2026 | B12: 0.044 | C12: 0.027 | D12: 0.058 | E12: 0.032 | F12: 0.026 | G12: Confirmed forecast
A13: 2027 | B13: 0.034 | C13: 0.022 | D13: 0.043 | E13: 0.021 | F13: 0.022 | G13: Confirmed forecast
A14: 2028 | B14: 0.031 | C14: 0.021 | D14: 0.04 | E14: 0.021 | F14: 0.02 | G14: Medium-term projection
A15: 2029 | B15: 0.029 | C15: 0.02 | D15: 0.037 | E15: 0.021 | F15: 0.02 | G15: Medium-term projection
A16: 2030 | B16: 0.028 | C16: 0.02 | D16: 0.035 | E16: 0.02 | F16: 0.02 | G16: Medium-term projection
A17: 2031 | B17: 0.027 | C17: 0.019 | D17: 0.033 | E17: 0.02 | F17: 0.019 | G17: Medium-term projection
A19: IMF Scenario Ranges for 2026–2027
A20: Scenario | B20: 2026 | C20: 2027 | D20: Description
A21: Reference scenario | B21: 0.044 | C21: 0.034 | D21: Baseline (confirmed forecast) | H21: Impact on CHD:
A22: Short-lived conflict | B22: 0.054 | C22: 0.045 | D22: Adverse scenario | H22: Global inflation directly affects CHD’s COGS (raw materials, packaging, freight), pricing power, and consumer demand elasticity.
A23: Prolonged disruption | B23: 0.058 | C23: 0.06 | D23: Extended energy shock - severe scenario | H23: US inflation normalizing to 2.0–2.1% by 2028+ supports CHD’s margin recovery and the 3% terminal growth assumption in the DCF.
A27: Global Real GDP Growth (2020–2031)
A28: Source: IMF World Economic Outlook, April 2025
A30: Year | B30: World | C30: Advanced | D30: Emerging | E30: US | F30: Euro Area
A31: 2020 | B31: -0.028 | C31: -0.042 | D31: -0.018 | E31: -0.028 | F31: -0.063
A32: 2021 | B32: 0.063 | C32: 0.054 | D32: 0.069 | E32: 0.059 | F32: 0.056
A33: 2022 | B33: 0.035 | C33: 0.027 | D33: 0.042 | E33: 0.019 | F33: 0.036
A34: 2023 | B34: 0.034 | C34: 0.017 | D34: 0.045 | E34: 0.029 | F34: 0.004
A35: 2024 | B35: 0.032 | C35: 0.018 | D35: 0.042 | E35: 0.028 | F35: 0.008
A36: 2025 | B36: 0.028 | C36: 0.014 | D36: 0.038 | E36: 0.016 | F36: 0.009
A37: 2026 | B37: 0.03 | C37: 0.015 | D37: 0.04 | E37: 0.017 | F37: 0.01
A38: 2027 | B38: 0.03 | C38: 0.016 | D38: 0.039 | E38: 0.018 | F38: 0.013
A39: 2028 | B39: 0.031 | C39: 0.016 | D39: 0.039 | E39: 0.019 | F39: 0.013
A40: 2029 | B40: 0.031 | C40: 0.016 | D40: 0.039 | E40: 0.02 | F40: 0.013
A41: 2030 | B41: 0.031 | C41: 0.016 | D41: 0.039 | E41: 0.02 | F41: 0.013
A42: 2031 | B42: 0.031 | C42: 0.016 | D42: 0.039 | E42: 0.02 | F42: 0.013
H43: Impact on CHD:
H44: US GDP slowing from 2.8% (2024) to 1.6–2.0% (2025–30) compresses consumer spending growth — CHD’s domestic segment (~77% of revenue) tracks household consumption closely.
H45: Emerging market GDP growth (3.8–4.0%) supports CHD’s international expansion (6.2% CAGR). Global GDP stabilizing at ~3.0–3.1% underpins the 3% terminal growth rate.
A47: Regional Factors
...
